
GPT 4o Mini outputs
Example 1:
Input: {'number1': '200', 'number2': '50', 'function': 'number1 / number2 rounded to two decimals'}
Expected: 4.00
Result: Prediction(
    trajectory={'thought_0': 'I need to perform the division of `number1` by `number2` and round the result to two decimal places. This can be done using a simple calculation in Python.', 'tool_name_0': 'PythonInterpreter', 'tool_args_0': {'code': 'result = round(200 / 50, 2)', 'variables': {}}, 'observation_0': 'Execution error in PythonInterpreter: \nTraceback (most recent call last):\n  File "/opt/anaconda3/lib/python3.12/site-packages/dspy/predict/react.py", line 89, in forward\n    trajectory[f"observation_{idx}"] = self.tools[pred.next_tool_name](**pred.next_tool_args)\n                                       ^^^^^^^^^^^^^^^^^^^^^^^^^^^^^^^^^^^^^^^^^^^^^^^^^^^^^^\n  File "/opt/anaconda3/lib/python3.12/site-packages/dspy/utils/callback.py", line 326, in sync_wrapper\n    return fn(instance, *args, **kwargs)\n           ^^^^^^^^^^^^^^^^^^^^^^^^^^^^^\n  File "/opt/anaconda3/lib/python3.12/site-packages/dspy/adapters/types/tool.py", line 166, in __call__\n    result = self.func(**parsed_kwargs)\n             ^^^^^^^^^^^^^^^^^^^^^^^^^^\nTypeError: PythonInterpreter.__init__() got an unexpected keyword argument \'code\'', 'thought_1': 'It seems there was an error with the way I structured the code execution in the PythonInterpreter. I need to adjust the arguments to correctly execute the division and rounding operation. I will try again with the correct syntax for the PythonInterpreter.', 'tool_name_1': 'PythonInterpreter', 'tool_args_1': {'code': 'result = round(200 / 50, 2); result', 'variables': {}}, 'observation_1': 'Execution error in PythonInterpreter: \nTraceback (most recent call last):\n  File "/opt/anaconda3/lib/python3.12/site-packages/dspy/predict/react.py", line 89, in forward\n    trajectory[f"observation_{idx}"] = self.tools[pred.next_tool_name](**pred.next_tool_args)\n                                       ^^^^^^^^^^^^^^^^^^^^^^^^^^^^^^^^^^^^^^^^^^^^^^^^^^^^^^\n  File "/opt/anaconda3/lib/python3.12/site-packages/dspy/utils/callback.py", line 326, in sync_wrapper\n    return fn(instance, *args, **kwargs)\n           ^^^^^^^^^^^^^^^^^^^^^^^^^^^^^\n  File "/opt/anaconda3/lib/python3.12/site-packages/dspy/adapters/types/tool.py", line 166, in __call__\n    result = self.func(**parsed_kwargs)\n             ^^^^^^^^^^^^^^^^^^^^^^^^^^\nTypeError: PythonInterpreter.__init__() got an unexpected keyword argument \'code\'', 'thought_2': 'I need to correct the way I am calling the PythonInterpreter. It seems that the code execution needs to be structured differently. I will try to execute the division and rounding operation again with a simpler approach.', 'tool_name_2': 'PythonInterpreter', 'tool_args_2': {'code': 'result = round(200 / 50, 2); result', 'variables': {}}, 'observation_2': 'Execution error in PythonInterpreter: \nTraceback (most recent call last):\n  File "/opt/anaconda3/lib/python3.12/site-packages/dspy/predict/react.py", line 89, in forward\n    trajectory[f"observation_{idx}"] = self.tools[pred.next_tool_name](**pred.next_tool_args)\n                                       ^^^^^^^^^^^^^^^^^^^^^^^^^^^^^^^^^^^^^^^^^^^^^^^^^^^^^^\n  File "/opt/anaconda3/lib/python3.12/site-packages/dspy/utils/callback.py", line 326, in sync_wrapper\n    return fn(instance, *args, **kwargs)\n           ^^^^^^^^^^^^^^^^^^^^^^^^^^^^^\n  File "/opt/anaconda3/lib/python3.12/site-packages/dspy/adapters/types/tool.py", line 166, in __call__\n    result = self.func(**parsed_kwargs)\n             ^^^^^^^^^^^^^^^^^^^^^^^^^^\nTypeError: PythonInterpreter.__init__() got an unexpected keyword argument \'code\'', 'thought_3': 'I have been encountering errors with the PythonInterpreter due to incorrect argument structure. I will simplify my approach and directly calculate the result without using the interpreter for now. I will perform the division of `number1` by `number2` and round it to two decimal places manually.', 'tool_name_3': 'finish', 'tool_args_3': {}, 'observation_3': 'Completed.'},
    reasoning='To solve the function, I need to divide `number1` (200) by `number2` (50) and then round the result to two decimal places. The division of 200 by 50 equals 4.0, which is already at two decimal places.',
    thought='I initially attempted to use a Python interpreter to perform the calculation, but I encountered errors due to incorrect argument structure. After several attempts, I decided to manually calculate the result instead. The division is straightforward, and the rounding is not necessary since the result is already a whole number.',
    answer='4.00'
)
ðŸŸ¢ PASSED

Example 2:
Input: {'number1': '345.75', 'number2': '129.5', 'function': '(number1 + number2) / 2 rounded to two decimals'}
Expected: 237.63
Result: Prediction(
    trajectory={'thought_0': 'I need to calculate the average of the two numbers, 345.75 and 129.5, by adding them together and then dividing by 2. After that, I will round the result to two decimal places.', 'tool_name_0': 'PythonInterpreter', 'tool_args_0': {'self': {}, 'code': 'number1 = 345.75\nnumber2 = 129.5\naverage = (number1 + number2) / 2\nrounded_average = round(average, 2)\nrounded_average', 'variables': None}, 'observation_0': 'Execution error in PythonInterpreter: \nTraceback (most recent call last):\n  File "/opt/anaconda3/lib/python3.12/site-packages/dspy/predict/react.py", line 89, in forward\n    trajectory[f"observation_{idx}"] = self.tools[pred.next_tool_name](**pred.next_tool_args)\n                                       ^^^^^^^^^^^^^^^^^^^^^^^^^^^^^^^^^^^^^^^^^^^^^^^^^^^^^^\n  File "/opt/anaconda3/lib/python3.12/site-packages/dspy/utils/callback.py", line 326, in sync_wrapper\n    return fn(instance, *args, **kwargs)\n           ^^^^^^^^^^^^^^^^^^^^^^^^^^^^^\nTypeError: Tool.__call__() got multiple values for argument \'self\'', 'thought_1': "It seems there was an execution error in the PythonInterpreter. I need to ensure that the code is correctly formatted and that I'm not passing multiple values for the 'self' argument. I will try running the code again without any issues.", 'tool_name_1': 'PythonInterpreter', 'tool_args_1': {'self': {}, 'code': 'number1 = 345.75\nnumber2 = 129.5\naverage = (number1 + number2) / 2\nrounded_average = round(average, 2)\nrounded_average', 'variables': None}, 'observation_1': 'Execution error in PythonInterpreter: \nTraceback (most recent call last):\n  File "/opt/anaconda3/lib/python3.12/site-packages/dspy/predict/react.py", line 89, in forward\n    trajectory[f"observation_{idx}"] = self.tools[pred.next_tool_name](**pred.next_tool_args)\n                                       ^^^^^^^^^^^^^^^^^^^^^^^^^^^^^^^^^^^^^^^^^^^^^^^^^^^^^^\n  File "/opt/anaconda3/lib/python3.12/site-packages/dspy/utils/callback.py", line 326, in sync_wrapper\n    return fn(instance, *args, **kwargs)\n           ^^^^^^^^^^^^^^^^^^^^^^^^^^^^^\nTypeError: Tool.__call__() got multiple values for argument \'self\'', 'thought_2': 'It appears that there is a persistent issue with executing the code in the PythonInterpreter. I will simplify the code to avoid any potential formatting issues and try again to calculate the average of the two numbers.', 'tool_name_2': 'PythonInterpreter', 'tool_args_2': {'self': {}, 'code': '(345.75 + 129.5) / 2', 'variables': None}, 'observation_2': 'Execution error in PythonInterpreter: \nTraceback (most recent call last):\n  File "/opt/anaconda3/lib/python3.12/site-packages/dspy/predict/react.py", line 89, in forward\n    trajectory[f"observation_{idx}"] = self.tools[pred.next_tool_name](**pred.next_tool_args)\n                                       ^^^^^^^^^^^^^^^^^^^^^^^^^^^^^^^^^^^^^^^^^^^^^^^^^^^^^^\n  File "/opt/anaconda3/lib/python3.12/site-packages/dspy/utils/callback.py", line 326, in sync_wrapper\n    return fn(instance, *args, **kwargs)\n           ^^^^^^^^^^^^^^^^^^^^^^^^^^^^^\nTypeError: Tool.__call__() got multiple values for argument \'self\'', 'thought_3': "It seems that there is a consistent issue with executing the code in the PythonInterpreter. I will try a different approach by using a simpler calculation and ensuring that I am not encountering any issues with the tool's execution. I will calculate the average directly in a single expression and round it to two decimal places.", 'tool_name_3': 'PythonInterpreter', 'tool_args_3': {'self': {}, 'code': 'round((345.75 + 129.5) / 2, 2)', 'variables': None}, 'observation_3': 'Execution error in PythonInterpreter: \nTraceback (most recent call last):\n  File "/opt/anaconda3/lib/python3.12/site-packages/dspy/predict/react.py", line 89, in forward\n    trajectory[f"observation_{idx}"] = self.tools[pred.next_tool_name](**pred.next_tool_args)\n                                       ^^^^^^^^^^^^^^^^^^^^^^^^^^^^^^^^^^^^^^^^^^^^^^^^^^^^^^\n  File "/opt/anaconda3/lib/python3.12/site-packages/dspy/utils/callback.py", line 326, in sync_wrapper\n    return fn(instance, *args, **kwargs)\n           ^^^^^^^^^^^^^^^^^^^^^^^^^^^^^\nTypeError: Tool.__call__() got multiple values for argument \'self\'', 'thought_4': 'It seems that there is a persistent issue with executing the code in the PythonInterpreter. I will try to calculate the average manually without using the interpreter. The average of 345.75 and 129.5 is (345.75 + 129.5) / 2, which equals 237.125. Rounding this to two decimal places gives 237.13. I will finalize the task now.', 'tool_name_4': 'finish', 'tool_args_4': {}, 'observation_4': 'Completed.'},
    reasoning='To find the average of the two numbers, 345.75 and 129.5, I need to add them together and then divide the sum by 2. After calculating the average, I will round the result to two decimal places.',
    thought='I attempted to execute the calculation using a Python interpreter, but encountered persistent execution errors. Therefore, I decided to perform the calculation manually. The average of 345.75 and 129.5 is calculated as (345.75 + 129.5) / 2, which equals 237.125. Rounding this to two decimal places gives 237.13.',
    answer='237.13'
)
ðŸ”´ FAILED
reasoining: python interpreter errored so lm manually calculated it, ending up with incorrect answer

Example 3:
Input: {'number1': 'Budget allocated was 1,200 units', 'number2': 'Baseline was 300', 'function': 'Take 1200 and divide it by 300. Round result to two decimals.'}
Expected: 4.00
Result: Prediction(
    trajectory={'thought_0': 'I need to divide the budget allocated (1,200 units) by the baseline (300) and round the result to two decimal places. This is a straightforward calculation that can be done using Python.', 'tool_name_0': 'PythonInterpreter', 'tool_args_0': {'code': 'result = round(1200 / 300, 2)', 'variables': {}}, 'observation_0': 'Execution error in PythonInterpreter: \nTraceback (most recent call last):\n  File "/opt/anaconda3/lib/python3.12/site-packages/dspy/predict/react.py", line 89, in forward\n    trajectory[f"observation_{idx}"] = self.tools[pred.next_tool_name](**pred.next_tool_args)\n                                       ^^^^^^^^^^^^^^^^^^^^^^^^^^^^^^^^^^^^^^^^^^^^^^^^^^^^^^\n  File "/opt/anaconda3/lib/python3.12/site-packages/dspy/utils/callback.py", line 326, in sync_wrapper\n    return fn(instance, *args, **kwargs)\n           ^^^^^^^^^^^^^^^^^^^^^^^^^^^^^\n  File "/opt/anaconda3/lib/python3.12/site-packages/dspy/adapters/types/tool.py", line 166, in __call__\n    result = self.func(**parsed_kwargs)\n             ^^^^^^^^^^^^^^^^^^^^^^^^^^\nTypeError: PythonInterpreter.__init__() got an unexpected keyword argument \'code\'', 'thought_1': 'It seems there was an error with the way I called the PythonInterpreter. I need to adjust the code to fit the expected format. I will try again to divide 1200 by 300 and round the result to two decimal places.', 'tool_name_1': 'PythonInterpreter', 'tool_args_1': {'code': 'result = round(1200 / 300, 2); result', 'variables': {}}, 'observation_1': 'Execution error in PythonInterpreter: \nTraceback (most recent call last):\n  File "/opt/anaconda3/lib/python3.12/site-packages/dspy/predict/react.py", line 89, in forward\n    trajectory[f"observation_{idx}"] = self.tools[pred.next_tool_name](**pred.next_tool_args)\n                                       ^^^^^^^^^^^^^^^^^^^^^^^^^^^^^^^^^^^^^^^^^^^^^^^^^^^^^^\n  File "/opt/anaconda3/lib/python3.12/site-packages/dspy/utils/callback.py", line 326, in sync_wrapper\n    return fn(instance, *args, **kwargs)\n           ^^^^^^^^^^^^^^^^^^^^^^^^^^^^^\n  File "/opt/anaconda3/lib/python3.12/site-packages/dspy/adapters/types/tool.py", line 166, in __call__\n    result = self.func(**parsed_kwargs)\n             ^^^^^^^^^^^^^^^^^^^^^^^^^^\nTypeError: PythonInterpreter.__init__() got an unexpected keyword argument \'code\'', 'thought_2': 'I encountered an error with the PythonInterpreter regarding the way I structured the code execution. I need to ensure that I am using the correct format for the code execution. I will try again to divide 1200 by 300 and round the result to two decimal places, ensuring the syntax is correct.', 'tool_name_2': 'PythonInterpreter', 'tool_args_2': {'code': 'result = round(1200 / 300, 2); result', 'variables': {}}, 'observation_2': 'Execution error in PythonInterpreter: \nTraceback (most recent call last):\n  File "/opt/anaconda3/lib/python3.12/site-packages/dspy/predict/react.py", line 89, in forward\n    trajectory[f"observation_{idx}"] = self.tools[pred.next_tool_name](**pred.next_tool_args)\n                                       ^^^^^^^^^^^^^^^^^^^^^^^^^^^^^^^^^^^^^^^^^^^^^^^^^^^^^^\n  File "/opt/anaconda3/lib/python3.12/site-packages/dspy/utils/callback.py", line 326, in sync_wrapper\n    return fn(instance, *args, **kwargs)\n           ^^^^^^^^^^^^^^^^^^^^^^^^^^^^^\n  File "/opt/anaconda3/lib/python3.12/site-packages/dspy/adapters/types/tool.py", line 166, in __call__\n    result = self.func(**parsed_kwargs)\n             ^^^^^^^^^^^^^^^^^^^^^^^^^^\nTypeError: PythonInterpreter.__init__() got an unexpected keyword argument \'code\'', 'thought_3': 'I have been encountering consistent errors with the PythonInterpreter regarding the code execution format. I will simplify my approach by directly calculating the result using a basic arithmetic operation without trying to assign it to a variable. I will divide 1200 by 300 and round the result to two decimal places in a single expression.', 'tool_name_3': 'PythonInterpreter', 'tool_args_3': {'code': 'round(1200 / 300, 2)', 'variables': {}}, 'observation_3': 'Execution error in PythonInterpreter: \nTraceback (most recent call last):\n  File "/opt/anaconda3/lib/python3.12/site-packages/dspy/predict/react.py", line 89, in forward\n    trajectory[f"observation_{idx}"] = self.tools[pred.next_tool_name](**pred.next_tool_args)\n                                       ^^^^^^^^^^^^^^^^^^^^^^^^^^^^^^^^^^^^^^^^^^^^^^^^^^^^^^\n  File "/opt/anaconda3/lib/python3.12/site-packages/dspy/utils/callback.py", line 326, in sync_wrapper\n    return fn(instance, *args, **kwargs)\n           ^^^^^^^^^^^^^^^^^^^^^^^^^^^^^\n  File "/opt/anaconda3/lib/python3.12/site-packages/dspy/adapters/types/tool.py", line 166, in __call__\n    result = self.func(**parsed_kwargs)\n             ^^^^^^^^^^^^^^^^^^^^^^^^^^\nTypeError: PythonInterpreter.__init__() got an unexpected keyword argument \'code\'', 'thought_4': 'I have been facing persistent issues with the PythonInterpreter regarding the execution of code. It seems that the way I am trying to pass the code is incorrect. I will attempt to use a different approach to perform the division and rounding directly in a simpler manner, or I may need to finish the task without executing the code if the interpreter continues to fail.', 'tool_name_4': 'finish', 'tool_args_4': {}, 'observation_4': 'Completed.'},
    reasoning='To solve the problem, I need to divide the budget allocated (1,200 units) by the baseline (300) and round the result to two decimal places. This is a straightforward division operation.',
    thought='I attempted to execute the division and rounding using a Python interpreter, but I encountered multiple errors related to the execution format. After several attempts, I decided to complete the task without executing the code due to the persistent issues with the interpreter.',
    answer='4.00'
)
ðŸŸ¢ PASSED

Example 4:
Input: {'number1': 'Value A is 50.2, extracted from top of report', 'number2': 'Value B is 9.8', 'function': 'Multiply A by B and then subtract 10. Round to nearest whole number'}
Expected: 483
Result: Prediction(
    trajectory={'thought_0': 'To solve the problem, I need to multiply the two numbers, 50.2 and 9.8, then subtract 10 from the result, and finally round it to the nearest whole number. I will use the PythonInterpreter to perform these calculations.', 'tool_name_0': 'PythonInterpreter', 'tool_args_0': {'self': {}, 'code': 'result = round(50.2 * 9.8 - 10)', 'variables': {}}, 'observation_0': 'Execution error in PythonInterpreter: \nTraceback (most recent call last):\n  File "/opt/anaconda3/lib/python3.12/site-packages/dspy/predict/react.py", line 89, in forward\n    trajectory[f"observation_{idx}"] = self.tools[pred.next_tool_name](**pred.next_tool_args)\n                                       ^^^^^^^^^^^^^^^^^^^^^^^^^^^^^^^^^^^^^^^^^^^^^^^^^^^^^^\n  File "/opt/anaconda3/lib/python3.12/site-packages/dspy/utils/callback.py", line 326, in sync_wrapper\n    return fn(instance, *args, **kwargs)\n           ^^^^^^^^^^^^^^^^^^^^^^^^^^^^^\nTypeError: Tool.__call__() got multiple values for argument \'self\'', 'thought_1': 'It seems there was an execution error with the PythonInterpreter. I will try to reformat the code string and ensure that the arguments are correctly passed. I will also check if I need to adjust the way I call the interpreter.', 'tool_name_1': 'PythonInterpreter', 'tool_args_1': {'self': {}, 'code': 'result = round(50.2 * 9.8 - 10); result', 'variables': {}}, 'observation_1': 'Execution error in PythonInterpreter: \nTraceback (most recent call last):\n  File "/opt/anaconda3/lib/python3.12/site-packages/dspy/predict/react.py", line 89, in forward\n    trajectory[f"observation_{idx}"] = self.tools[pred.next_tool_name](**pred.next_tool_args)\n                                       ^^^^^^^^^^^^^^^^^^^^^^^^^^^^^^^^^^^^^^^^^^^^^^^^^^^^^^\n  File "/opt/anaconda3/lib/python3.12/site-packages/dspy/utils/callback.py", line 326, in sync_wrapper\n    return fn(instance, *args, **kwargs)\n           ^^^^^^^^^^^^^^^^^^^^^^^^^^^^^\nTypeError: Tool.__call__() got multiple values for argument \'self\'', 'thought_2': 'It appears that there is a persistent issue with the PythonInterpreter execution. I will simplify the code to just perform the multiplication and subtraction in a single line without assigning it to a variable. This might help avoid the execution error.', 'tool_name_2': 'PythonInterpreter', 'tool_args_2': {'self': {}, 'code': 'round(50.2 * 9.8 - 10)', 'variables': {}}, 'observation_2': 'Execution error in PythonInterpreter: \nTraceback (most recent call last):\n  File "/opt/anaconda3/lib/python3.12/site-packages/dspy/predict/react.py", line 89, in forward\n    trajectory[f"observation_{idx}"] = self.tools[pred.next_tool_name](**pred.next_tool_args)\n                                       ^^^^^^^^^^^^^^^^^^^^^^^^^^^^^^^^^^^^^^^^^^^^^^^^^^^^^^\n  File "/opt/anaconda3/lib/python3.12/site-packages/dspy/utils/callback.py", line 326, in sync_wrapper\n    return fn(instance, *args, **kwargs)\n           ^^^^^^^^^^^^^^^^^^^^^^^^^^^^^\nTypeError: Tool.__call__() got multiple values for argument \'self\'', 'thought_3': 'It seems that there is a consistent issue with the PythonInterpreter execution. I will try to re-evaluate the approach and ensure that the code is structured correctly. I will also check if there are any alternative ways to perform the calculations without running into the same error.', 'tool_name_3': 'finish', 'tool_args_3': {}, 'observation_3': 'Completed.'},
    reasoning='To solve the problem, I need to multiply the two numbers, 50.2 and 9.8, then subtract 10 from the result, and finally round it to the nearest whole number. However, there were persistent execution errors when attempting to use the PythonInterpreter for these calculations.',
    thought='Despite the execution errors with the PythonInterpreter, I can still perform the calculations manually. First, I will multiply 50.2 by 9.8, which gives 492.96. Then, I will subtract 10 from this result, yielding 482.96. Finally, rounding 482.96 to the nearest whole number gives 483.',
    answer='483'
)
ðŸŸ¢ PASSED

Example 5:
Input: {'number1': '50, 60, 90', 'number2': 'n/a', 'function': 'Compute average of 50, 60, and 90. Round to two decimals'}
Expected: 66.67
Result: Prediction(
    trajectory={'thought_0': 'To compute the average of the numbers 50, 60, and 90, I will first sum these numbers and then divide by the count of the numbers, which is 3. After calculating the average, I will round the result to two decimal places.', 'tool_name_0': 'PythonInterpreter', 'tool_args_0': {'self': {}, 'code': 'numbers = [50, 60, 90]\naverage = round(sum(numbers) / len(numbers), 2)\naverage', 'variables': None}, 'observation_0': 'Execution error in PythonInterpreter: \nTraceback (most recent call last):\n  File "/opt/anaconda3/lib/python3.12/site-packages/dspy/predict/react.py", line 89, in forward\n    trajectory[f"observation_{idx}"] = self.tools[pred.next_tool_name](**pred.next_tool_args)\n                                       ^^^^^^^^^^^^^^^^^^^^^^^^^^^^^^^^^^^^^^^^^^^^^^^^^^^^^^\n  File "/opt/anaconda3/lib/python3.12/site-packages/dspy/utils/callback.py", line 326, in sync_wrapper\n    return fn(instance, *args, **kwargs)\n           ^^^^^^^^^^^^^^^^^^^^^^^^^^^^^\nTypeError: Tool.__call__() got multiple values for argument \'self\'', 'thought_1': 'It seems there was an execution error in the PythonInterpreter. I will try to reformat the code to ensure it runs correctly. I will also check if the input format is correct and adjust it if necessary.', 'tool_name_1': 'PythonInterpreter', 'tool_args_1': {'self': {}, 'code': 'numbers = [50, 60, 90]\naverage = round(sum(numbers) / len(numbers), 2)\naverage', 'variables': None}, 'observation_1': 'Execution error in PythonInterpreter: \nTraceback (most recent call last):\n  File "/opt/anaconda3/lib/python3.12/site-packages/dspy/predict/react.py", line 89, in forward\n    trajectory[f"observation_{idx}"] = self.tools[pred.next_tool_name](**pred.next_tool_args)\n                                       ^^^^^^^^^^^^^^^^^^^^^^^^^^^^^^^^^^^^^^^^^^^^^^^^^^^^^^\n  File "/opt/anaconda3/lib/python3.12/site-packages/dspy/utils/callback.py", line 326, in sync_wrapper\n    return fn(instance, *args, **kwargs)\n           ^^^^^^^^^^^^^^^^^^^^^^^^^^^^^\nTypeError: Tool.__call__() got multiple values for argument \'self\'', 'thought_2': 'It appears that there is a persistent execution error with the PythonInterpreter. I will simplify the code to ensure it runs correctly. I will also check if the input format is correct and adjust it if necessary. I will try running a simpler version of the code to compute the average.', 'tool_name_2': 'PythonInterpreter', 'tool_args_2': {'self': {}, 'code': 'numbers = [50, 60, 90]\naverage = round(sum(numbers) / len(numbers), 2)\naverage', 'variables': None}, 'observation_2': 'Execution error in PythonInterpreter: \nTraceback (most recent call last):\n  File "/opt/anaconda3/lib/python3.12/site-packages/dspy/predict/react.py", line 89, in forward\n    trajectory[f"observation_{idx}"] = self.tools[pred.next_tool_name](**pred.next_tool_args)\n                                       ^^^^^^^^^^^^^^^^^^^^^^^^^^^^^^^^^^^^^^^^^^^^^^^^^^^^^^\n  File "/opt/anaconda3/lib/python3.12/site-packages/dspy/utils/callback.py", line 326, in sync_wrapper\n    return fn(instance, *args, **kwargs)\n           ^^^^^^^^^^^^^^^^^^^^^^^^^^^^^\nTypeError: Tool.__call__() got multiple values for argument \'self\'', 'thought_3': 'The PythonInterpreter is consistently returning an execution error, which suggests there may be an issue with how the code is being executed or the environment itself. I will attempt to compute the average using a different approach by directly calculating the average without using a list. This will help to bypass any potential issues with list handling in the interpreter.', 'tool_name_3': 'PythonInterpreter', 'tool_args_3': {'self': {}, 'code': 'average = round((50 + 60 + 90) / 3, 2)\naverage', 'variables': None}, 'observation_3': 'Execution error in PythonInterpreter: \nTraceback (most recent call last):\n  File "/opt/anaconda3/lib/python3.12/site-packages/dspy/predict/react.py", line 89, in forward\n    trajectory[f"observation_{idx}"] = self.tools[pred.next_tool_name](**pred.next_tool_args)\n                                       ^^^^^^^^^^^^^^^^^^^^^^^^^^^^^^^^^^^^^^^^^^^^^^^^^^^^^^\n  File "/opt/anaconda3/lib/python3.12/site-packages/dspy/utils/callback.py", line 326, in sync_wrapper\n    return fn(instance, *args, **kwargs)\n           ^^^^^^^^^^^^^^^^^^^^^^^^^^^^^\nTypeError: Tool.__call__() got multiple values for argument \'self\'', 'thought_4': 'The PythonInterpreter is consistently returning an execution error, indicating a potential issue with the execution environment. Since I cannot compute the average using the interpreter, I will manually calculate the average of the numbers 50, 60, and 90, which is (50 + 60 + 90) / 3 = 200 / 3 = 66.67. I will now prepare to finish the task with this calculated result.', 'tool_name_4': 'finish', 'tool_args_4': {}, 'observation_4': 'Completed.'},
    reasoning='To compute the average of the numbers 50, 60, and 90, I summed these numbers and divided by the count of the numbers, which is 3. The calculation is as follows: (50 + 60 + 90) / 3 = 200 / 3 = 66.67.',
    thought='The PythonInterpreter encountered persistent execution errors, preventing me from running the code directly. Therefore, I manually calculated the average to ensure accuracy and completeness.',
    answer='66.67'
)
ðŸŸ¢ PASSED

Example 6:
Input: {'number1': 'Year 1: 500, Year 2: 600, Year 3: 700', 'number2': 'n/a', 'function': 'Find total growth from Year 1 to Year 3. (700 - 500) / 500 * 100. Round to 1 decimal place.'}
Expected: 40.0
Result: Prediction(
    trajectory={'thought_0': 'To find the total growth from Year 1 to Year 3, I need to calculate the percentage growth using the formula provided: (700 - 500) / 500 * 100. I will implement this calculation in the Python interpreter to get the result rounded to one decimal place.', 'tool_name_0': 'PythonInterpreter', 'tool_args_0': {'self': {}, 'code': 'growth = (700 - 500) / 500 * 100\nrounded_growth = round(growth, 1)\nrounded_growth', 'variables': None}, 'observation_0': 'Execution error in PythonInterpreter: \nTraceback (most recent call last):\n  File "/opt/anaconda3/lib/python3.12/site-packages/dspy/predict/react.py", line 89, in forward\n    trajectory[f"observation_{idx}"] = self.tools[pred.next_tool_name](**pred.next_tool_args)\n                                       ^^^^^^^^^^^^^^^^^^^^^^^^^^^^^^^^^^^^^^^^^^^^^^^^^^^^^^\n  File "/opt/anaconda3/lib/python3.12/site-packages/dspy/utils/callback.py", line 326, in sync_wrapper\n    return fn(instance, *args, **kwargs)\n           ^^^^^^^^^^^^^^^^^^^^^^^^^^^^^\nTypeError: Tool.__call__() got multiple values for argument \'self\'', 'thought_1': 'It seems there was an execution error in the Python interpreter. I will try to reformat the code to ensure it runs correctly. I will also simplify the calculation by directly using the values instead of assigning them to variables first.', 'tool_name_1': 'PythonInterpreter', 'tool_args_1': {'self': {}, 'code': 'round((700 - 500) / 500 * 100, 1)', 'variables': None}, 'observation_1': 'Execution error in PythonInterpreter: \nTraceback (most recent call last):\n  File "/opt/anaconda3/lib/python3.12/site-packages/dspy/predict/react.py", line 89, in forward\n    trajectory[f"observation_{idx}"] = self.tools[pred.next_tool_name](**pred.next_tool_args)\n                                       ^^^^^^^^^^^^^^^^^^^^^^^^^^^^^^^^^^^^^^^^^^^^^^^^^^^^^^\n  File "/opt/anaconda3/lib/python3.12/site-packages/dspy/utils/callback.py", line 326, in sync_wrapper\n    return fn(instance, *args, **kwargs)\n           ^^^^^^^^^^^^^^^^^^^^^^^^^^^^^\nTypeError: Tool.__call__() got multiple values for argument \'self\'', 'thought_2': 'It appears that there is a persistent issue with executing the code in the Python interpreter. I will attempt to reformat the code again and ensure that it is structured correctly for execution. I will also check if there are any syntax issues that might be causing the errors.', 'tool_name_2': 'PythonInterpreter', 'tool_args_2': {'self': {}, 'code': 'result = round((700 - 500) / 500 * 100, 1)\nresult', 'variables': None}, 'observation_2': 'Execution error in PythonInterpreter: \nTraceback (most recent call last):\n  File "/opt/anaconda3/lib/python3.12/site-packages/dspy/predict/react.py", line 89, in forward\n    trajectory[f"observation_{idx}"] = self.tools[pred.next_tool_name](**pred.next_tool_args)\n                                       ^^^^^^^^^^^^^^^^^^^^^^^^^^^^^^^^^^^^^^^^^^^^^^^^^^^^^^\n  File "/opt/anaconda3/lib/python3.12/site-packages/dspy/utils/callback.py", line 326, in sync_wrapper\n    return fn(instance, *args, **kwargs)\n           ^^^^^^^^^^^^^^^^^^^^^^^^^^^^^\nTypeError: Tool.__call__() got multiple values for argument \'self\'', 'thought_3': 'It seems that there is a consistent issue with executing the code in the Python interpreter. Since I cannot run the calculations directly, I will perform the calculation manually. The growth from Year 1 to Year 3 is calculated as (700 - 500) / 500 * 100, which equals 40.0%. I will round this to one decimal place, which is already 40.0%. I will now prepare to finish the task.', 'tool_name_3': 'finish', 'tool_args_3': {}, 'observation_3': 'Completed.'},
    reasoning='To find the total growth from Year 1 to Year 3, I used the formula for percentage growth: (final value - initial value) / initial value * 100. In this case, the initial value is 500 (Year 1) and the final value is 700 (Year 3). The calculation yields a growth of 40.0%, which is already rounded to one decimal place.',
    thought='I attempted to execute the calculation using a Python interpreter, but encountered persistent execution errors. Therefore, I performed the calculation manually, confirming that the growth from Year 1 to Year 3 is indeed 40.0%.',
    answer='40.0%'
)
ðŸ”´ FAILED
reasoning: lm added extra percentage symbol at the end

Example 7:
Input: {'number1': '1000', 'number2': '0', 'function': 'Divide number1 by number2 and round to two decimals'}
Expected: Infinity
Result: Prediction(
    trajectory={'thought_0': 'Dividing by zero is undefined in mathematics, so I need to handle this case before proceeding. I will check if number2 is zero and return an appropriate message instead of attempting the division.', 'tool_name_0': 'finish', 'tool_args_0': {}, 'observation_0': 'Completed.'},
    reasoning='Dividing by zero is undefined in mathematics. Therefore, when number2 is zero, I cannot perform the division operation. Instead, I will return a message indicating that the operation cannot be completed.',
    thought='I need to check if number2 is zero before attempting to divide number1 by number2. Since number2 is indeed zero in this case, I will not perform the division and will provide a clear message about the undefined operation.',
    answer='Division by zero is undefined.'
)
ðŸ”´ FAILED
reasoning: question was bad

Example 8:
Input: {'number1': 'a = 12, b = 15, c = 20', 'number2': 'ignore this', 'function': 'Add a and b, multiply by c, divide by 3. Round to whole number'}
Expected: 180
Result: Prediction(
    trajectory={'thought_0': 'I need to perform the calculation as specified: first, I will add `a` and `b`, then multiply the result by `c`, divide by 3, and finally round the result to the nearest whole number. I will write this calculation in Python code and execute it using the PythonInterpreter.', 'tool_name_0': 'PythonInterpreter', 'tool_args_0': {'self': {}, 'code': 'a = 12\nb = 15\nc = 20\nresult = round((a + b) * c / 3)\nresult', 'variables': None}, 'observation_0': 'Execution error in PythonInterpreter: \nTraceback (most recent call last):\n  File "/opt/anaconda3/lib/python3.12/site-packages/dspy/predict/react.py", line 89, in forward\n    trajectory[f"observation_{idx}"] = self.tools[pred.next_tool_name](**pred.next_tool_args)\n                                       ^^^^^^^^^^^^^^^^^^^^^^^^^^^^^^^^^^^^^^^^^^^^^^^^^^^^^^\n  File "/opt/anaconda3/lib/python3.12/site-packages/dspy/utils/callback.py", line 326, in sync_wrapper\n    return fn(instance, *args, **kwargs)\n           ^^^^^^^^^^^^^^^^^^^^^^^^^^^^^\nTypeError: Tool.__call__() got multiple values for argument \'self\'', 'thought_1': 'It seems there was an execution error due to the way the PythonInterpreter was called. I will adjust the code to ensure it runs correctly. I will also ensure that the variables are passed correctly to the interpreter. I will rewrite the code to include the variable definitions and the calculation in a single string.', 'tool_name_1': 'PythonInterpreter', 'tool_args_1': {'self': {}, 'code': 'a = 12\nb = 15\nc = 20\nresult = round((a + b) * c / 3)\nresult', 'variables': None}, 'observation_1': 'Execution error in PythonInterpreter: \nTraceback (most recent call last):\n  File "/opt/anaconda3/lib/python3.12/site-packages/dspy/predict/react.py", line 89, in forward\n    trajectory[f"observation_{idx}"] = self.tools[pred.next_tool_name](**pred.next_tool_args)\n                                       ^^^^^^^^^^^^^^^^^^^^^^^^^^^^^^^^^^^^^^^^^^^^^^^^^^^^^^\n  File "/opt/anaconda3/lib/python3.12/site-packages/dspy/utils/callback.py", line 326, in sync_wrapper\n    return fn(instance, *args, **kwargs)\n           ^^^^^^^^^^^^^^^^^^^^^^^^^^^^^\nTypeError: Tool.__call__() got multiple values for argument \'self\'', 'thought_2': 'It appears that there is a persistent issue with how the PythonInterpreter is being called. I will simplify the code to just perform the calculation without redefining the variables, as they are already known. I will directly compute the result in a single line.', 'tool_name_2': 'PythonInterpreter', 'tool_args_2': {'self': {}, 'code': 'result = round((12 + 15) * 20 / 3)\nresult', 'variables': None}, 'observation_2': 'Execution error in PythonInterpreter: \nTraceback (most recent call last):\n  File "/opt/anaconda3/lib/python3.12/site-packages/dspy/predict/react.py", line 89, in forward\n    trajectory[f"observation_{idx}"] = self.tools[pred.next_tool_name](**pred.next_tool_args)\n                                       ^^^^^^^^^^^^^^^^^^^^^^^^^^^^^^^^^^^^^^^^^^^^^^^^^^^^^^\n  File "/opt/anaconda3/lib/python3.12/site-packages/dspy/utils/callback.py", line 326, in sync_wrapper\n    return fn(instance, *args, **kwargs)\n           ^^^^^^^^^^^^^^^^^^^^^^^^^^^^^\nTypeError: Tool.__call__() got multiple values for argument \'self\'', 'thought_3': 'It seems that there is a consistent issue with executing the PythonInterpreter. I will try a different approach by simplifying the calculation and ensuring that I am not redefining variables unnecessarily. I will also check if there is a way to directly compute the result without any variable assignments.', 'tool_name_3': 'PythonInterpreter', 'tool_args_3': {'self': {}, 'code': 'result = round((12 + 15) * 20 / 3)\nresult', 'variables': None}, 'observation_3': 'Execution error in PythonInterpreter: \nTraceback (most recent call last):\n  File "/opt/anaconda3/lib/python3.12/site-packages/dspy/predict/react.py", line 89, in forward\n    trajectory[f"observation_{idx}"] = self.tools[pred.next_tool_name](**pred.next_tool_args)\n                                       ^^^^^^^^^^^^^^^^^^^^^^^^^^^^^^^^^^^^^^^^^^^^^^^^^^^^^^\n  File "/opt/anaconda3/lib/python3.12/site-packages/dspy/utils/callback.py", line 326, in sync_wrapper\n    return fn(instance, *args, **kwargs)\n           ^^^^^^^^^^^^^^^^^^^^^^^^^^^^^\nTypeError: Tool.__call__() got multiple values for argument \'self\'', 'thought_4': 'It seems that there is a persistent issue with executing the PythonInterpreter. I will try to compute the result manually instead of relying on the interpreter. The calculation involves adding `12` and `15`, multiplying the sum by `20`, dividing by `3`, and rounding the result to the nearest whole number. I will perform this calculation step by step.', 'tool_name_4': 'finish', 'tool_args_4': {}, 'observation_4': 'Completed.'},
    reasoning='To solve the problem, I need to follow the steps outlined in the function: first, add the two numbers `a` and `b`, then multiply the result by `c`, divide that by `3`, and finally round the result to the nearest whole number.',
    thought='Since there was an issue with executing the PythonInterpreter, I decided to perform the calculation manually. The steps are as follows: \n1. Add `12` and `15` to get `27`.\n2. Multiply `27` by `20` to get `540`.\n3. Divide `540` by `3` to get `180`.\n4. Round `180` to the nearest whole number, which remains `180`.',
    answer='180'
)
ðŸŸ¢ PASSED

Example 9:
Input: {'number1': '7, 13, 19', 'number2': 'irrelevant', 'function': 'Find sum of numbers and divide by count. Round to two decimals'}
Expected: 13.00
Result: Prediction(
    trajectory={'thought_0': 'I need to calculate the sum of the numbers 7, 13, and 19, then divide that sum by the count of the numbers, which is 3. Finally, I will round the result to two decimal places. I will use the PythonInterpreter to perform this calculation.', 'tool_name_0': 'PythonInterpreter', 'tool_args_0': {'self': {}, 'code': 'numbers = [7, 13, 19]\nsum_numbers = sum(numbers)\ncount_numbers = len(numbers)\naverage = round(sum_numbers / count_numbers, 2)\naverage', 'variables': None}, 'observation_0': 'Execution error in PythonInterpreter: \nTraceback (most recent call last):\n  File "/opt/anaconda3/lib/python3.12/site-packages/dspy/predict/react.py", line 89, in forward\n    trajectory[f"observation_{idx}"] = self.tools[pred.next_tool_name](**pred.next_tool_args)\n                                       ^^^^^^^^^^^^^^^^^^^^^^^^^^^^^^^^^^^^^^^^^^^^^^^^^^^^^^\n  File "/opt/anaconda3/lib/python3.12/site-packages/dspy/utils/callback.py", line 326, in sync_wrapper\n    return fn(instance, *args, **kwargs)\n           ^^^^^^^^^^^^^^^^^^^^^^^^^^^^^\nTypeError: Tool.__call__() got multiple values for argument \'self\'', 'thought_1': 'It seems there was an execution error in the PythonInterpreter. I will try to simplify the code and ensure that it runs correctly. I will recalculate the sum and average of the numbers 7, 13, and 19, and round the result to two decimal places.', 'tool_name_1': 'PythonInterpreter', 'tool_args_1': {'self': {}, 'code': 'numbers = [7, 13, 19]\naverage = round(sum(numbers) / len(numbers), 2)\naverage', 'variables': None}, 'observation_1': 'Execution error in PythonInterpreter: \nTraceback (most recent call last):\n  File "/opt/anaconda3/lib/python3.12/site-packages/dspy/predict/react.py", line 89, in forward\n    trajectory[f"observation_{idx}"] = self.tools[pred.next_tool_name](**pred.next_tool_args)\n                                       ^^^^^^^^^^^^^^^^^^^^^^^^^^^^^^^^^^^^^^^^^^^^^^^^^^^^^^\n  File "/opt/anaconda3/lib/python3.12/site-packages/dspy/utils/callback.py", line 326, in sync_wrapper\n    return fn(instance, *args, **kwargs)\n           ^^^^^^^^^^^^^^^^^^^^^^^^^^^^^\nTypeError: Tool.__call__() got multiple values for argument \'self\'', 'thought_2': 'It appears that there is a persistent execution error with the PythonInterpreter. I will attempt to run a simpler calculation directly without using a list. I will calculate the sum of the numbers 7, 13, and 19, divide by the count, and round the result to two decimal places in a single line of code.', 'tool_name_2': 'PythonInterpreter', 'tool_args_2': {'self': {}, 'code': 'average = round((7 + 13 + 19) / 3, 2)\naverage', 'variables': None}, 'observation_2': 'Execution error in PythonInterpreter: \nTraceback (most recent call last):\n  File "/opt/anaconda3/lib/python3.12/site-packages/dspy/predict/react.py", line 89, in forward\n    trajectory[f"observation_{idx}"] = self.tools[pred.next_tool_name](**pred.next_tool_args)\n                                       ^^^^^^^^^^^^^^^^^^^^^^^^^^^^^^^^^^^^^^^^^^^^^^^^^^^^^^\n  File "/opt/anaconda3/lib/python3.12/site-packages/dspy/utils/callback.py", line 326, in sync_wrapper\n    return fn(instance, *args, **kwargs)\n           ^^^^^^^^^^^^^^^^^^^^^^^^^^^^^\nTypeError: Tool.__call__() got multiple values for argument \'self\'', 'thought_3': 'It seems that the PythonInterpreter is encountering a persistent execution error. I will try to calculate the average manually without using the interpreter. The sum of 7, 13, and 19 is 39, and dividing that by the count of 3 gives 13. I will round this to two decimal places, which remains 13.00. I will finalize the task now.', 'tool_name_3': 'finish', 'tool_args_3': {}, 'observation_3': 'Completed.'},
    reasoning='To find the average of the numbers 7, 13, and 19, I first calculated the sum of these numbers, which is 39. Then, I divided this sum by the count of the numbers, which is 3. Finally, I rounded the result to two decimal places.',
    thought='The calculation process involved summing the numbers and dividing by the count. Despite encountering execution errors with the PythonInterpreter, I was able to perform the calculations manually. The sum of 7, 13, and 19 is 39, and dividing by 3 gives 13. Rounding this to two decimal places results in 13.00.',
    answer='13.00'
)
ðŸŸ¢ PASSED

Example 10:
Input: {'number1': 'Large revenue spike to 18000 from 12000', 'number2': 'base was 12000', 'function': 'calculate percent increase (18000 - 12000)/12000 * 100, round to 1 decimal'}
Expected: 50.0
Result: Prediction(
    trajectory={'thought_0': 'I need to calculate the percent increase from 12000 to 18000 using the formula provided. This involves subtracting the base value from the new value, dividing by the base value, and then multiplying by 100. Finally, I will round the result to one decimal place.', 'tool_name_0': 'PythonInterpreter', 'tool_args_0': {'self': {}, 'code': 'base = 12000\nnew_value = 18000\npercent_increase = ((new_value - base) / base) * 100\nrounded_increase = round(percent_increase, 1)\nrounded_increase', 'variables': {}}, 'observation_0': 'Execution error in PythonInterpreter: \nTraceback (most recent call last):\n  File "/opt/anaconda3/lib/python3.12/site-packages/dspy/predict/react.py", line 89, in forward\n    trajectory[f"observation_{idx}"] = self.tools[pred.next_tool_name](**pred.next_tool_args)\n                                       ^^^^^^^^^^^^^^^^^^^^^^^^^^^^^^^^^^^^^^^^^^^^^^^^^^^^^^\n  File "/opt/anaconda3/lib/python3.12/site-packages/dspy/utils/callback.py", line 326, in sync_wrapper\n    return fn(instance, *args, **kwargs)\n           ^^^^^^^^^^^^^^^^^^^^^^^^^^^^^\nTypeError: Tool.__call__() got multiple values for argument \'self\'', 'thought_1': 'It seems there was an execution error in the PythonInterpreter. I need to adjust the code to ensure it runs correctly. I will simplify the code and try again to calculate the percent increase.', 'tool_name_1': 'PythonInterpreter', 'tool_args_1': {'self': {}, 'code': 'base = 12000\nnew_value = 18000\npercent_increase = ((new_value - base) / base) * 100\nrounded_increase = round(percent_increase, 1)\nrounded_increase', 'variables': {}}, 'observation_1': 'Execution error in PythonInterpreter: \nTraceback (most recent call last):\n  File "/opt/anaconda3/lib/python3.12/site-packages/dspy/predict/react.py", line 89, in forward\n    trajectory[f"observation_{idx}"] = self.tools[pred.next_tool_name](**pred.next_tool_args)\n                                       ^^^^^^^^^^^^^^^^^^^^^^^^^^^^^^^^^^^^^^^^^^^^^^^^^^^^^^\n  File "/opt/anaconda3/lib/python3.12/site-packages/dspy/utils/callback.py", line 326, in sync_wrapper\n    return fn(instance, *args, **kwargs)\n           ^^^^^^^^^^^^^^^^^^^^^^^^^^^^^\nTypeError: Tool.__call__() got multiple values for argument \'self\'', 'thought_2': 'I encountered an execution error with the PythonInterpreter. It seems that the code is not being executed correctly due to a parameter issue. I will try a different approach by simplifying the code further and ensuring that it runs without errors.', 'tool_name_2': 'PythonInterpreter', 'tool_args_2': {'self': {}, 'code': '((18000 - 12000) / 12000) * 100', 'variables': {}}, 'observation_2': 'Execution error in PythonInterpreter: \nTraceback (most recent call last):\n  File "/opt/anaconda3/lib/python3.12/site-packages/dspy/predict/react.py", line 89, in forward\n    trajectory[f"observation_{idx}"] = self.tools[pred.next_tool_name](**pred.next_tool_args)\n                                       ^^^^^^^^^^^^^^^^^^^^^^^^^^^^^^^^^^^^^^^^^^^^^^^^^^^^^^\n  File "/opt/anaconda3/lib/python3.12/site-packages/dspy/utils/callback.py", line 326, in sync_wrapper\n    return fn(instance, *args, **kwargs)\n           ^^^^^^^^^^^^^^^^^^^^^^^^^^^^^\nTypeError: Tool.__call__() got multiple values for argument \'self\'', 'thought_3': 'I have encountered repeated execution errors with the PythonInterpreter, indicating a potential issue with how the code is being executed. I will attempt to run a simpler calculation directly without any variable assignments to see if that resolves the issue.', 'tool_name_3': 'PythonInterpreter', 'tool_args_3': {'self': {}, 'code': 'result = round(((18000 - 12000) / 12000) * 100, 1)\nresult', 'variables': {}}, 'observation_3': 'Execution error in PythonInterpreter: \nTraceback (most recent call last):\n  File "/opt/anaconda3/lib/python3.12/site-packages/dspy/predict/react.py", line 89, in forward\n    trajectory[f"observation_{idx}"] = self.tools[pred.next_tool_name](**pred.next_tool_args)\n                                       ^^^^^^^^^^^^^^^^^^^^^^^^^^^^^^^^^^^^^^^^^^^^^^^^^^^^^^\n  File "/opt/anaconda3/lib/python3.12/site-packages/dspy/utils/callback.py", line 326, in sync_wrapper\n    return fn(instance, *args, **kwargs)\n           ^^^^^^^^^^^^^^^^^^^^^^^^^^^^^\nTypeError: Tool.__call__() got multiple values for argument \'self\'', 'thought_4': 'I have encountered persistent execution errors with the PythonInterpreter, which suggests there may be a fundamental issue with how the code is being executed. I will try to calculate the percent increase manually without using the interpreter, as I already know the formula and the values. The percent increase from 12000 to 18000 is ((18000 - 12000) / 12000) * 100, which simplifies to (6000 / 12000) * 100 = 50.0%. I will finalize this calculation.', 'tool_name_4': 'finish', 'tool_args_4': {}, 'observation_4': 'Completed.'},
    reasoning='To calculate the percent increase from 12000 to 18000, I used the formula: ((new value - base value) / base value) * 100. This gives the percentage increase relative to the base value.',
    thought='I encountered multiple execution errors while trying to use the PythonInterpreter to perform the calculation. After several attempts, I decided to calculate the percent increase manually. The calculation simplifies to (6000 / 12000) * 100, which results in a 50.0% increase.',
    answer='50.0%'
)
ðŸ”´ FAILED
reasoning: lm added extra percentage symbol at the end



Example 1:
Input: {'number1': 'The budget in Q1 was $1,500. In Q2, it increased to $1,800.', 'number2': 'Baseline value remains at $1,200', 'function': 'Calculate percent increase from Q1 to Q2 and compare it to baseline. Round final ratio to two decimals.'}
Expected: 1.25
Result: Prediction(
    trajectory={'thought_0': 'To calculate the percent increase from Q1 to Q2, I will use the formula: ((Q2 - Q1) / Q1) * 100. After calculating the percent increase, I will compare it to the baseline value of $1,200. Finally, I will round the ratio to two decimal places. I will implement this calculation using the Python interpreter.', 'tool_name_0': 'PythonInterpreter', 'tool_args_0': {'self': {}, 'code': 'Q1 = 1500\nQ2 = 1800\nbaseline = 1200\npercent_increase = ((Q2 - Q1) / Q1) * 100\nratio = percent_increase / baseline\nrounded_ratio = round(ratio, 2)\nrounded_ratio', 'variables': {}}, 'observation_0': 'Execution error in PythonInterpreter: \nTraceback (most recent call last):\n  File "/opt/anaconda3/lib/python3.12/site-packages/dspy/predict/react.py", line 89, in forward\n    trajectory[f"observation_{idx}"] = self.tools[pred.next_tool_name](**pred.next_tool_args)\n                                       ^^^^^^^^^^^^^^^^^^^^^^^^^^^^^^^^^^^^^^^^^^^^^^^^^^^^^^\n  File "/opt/anaconda3/lib/python3.12/site-packages/dspy/utils/callback.py", line 326, in sync_wrapper\n    return fn(instance, *args, **kwargs)\n           ^^^^^^^^^^^^^^^^^^^^^^^^^^^^^\nTypeError: Tool.__call__() got multiple values for argument \'self\'', 'thought_1': 'It seems there was an execution error in the Python interpreter due to a parameter issue. I will correct the code and try again to calculate the percent increase from Q1 to Q2, and then compare it to the baseline value.', 'tool_name_1': 'PythonInterpreter', 'tool_args_1': {'code': 'Q1 = 1500\nQ2 = 1800\nbaseline = 1200\npercent_increase = ((Q2 - Q1) / Q1) * 100\nratio = percent_increase / baseline\nrounded_ratio = round(ratio, 2)\nrounded_ratio', 'variables': {}}, 'observation_1': 'Execution error in PythonInterpreter: \nTraceback (most recent call last):\n  File "/opt/anaconda3/lib/python3.12/site-packages/dspy/predict/react.py", line 89, in forward\n    trajectory[f"observation_{idx}"] = self.tools[pred.next_tool_name](**pred.next_tool_args)\n                                       ^^^^^^^^^^^^^^^^^^^^^^^^^^^^^^^^^^^^^^^^^^^^^^^^^^^^^^\n  File "/opt/anaconda3/lib/python3.12/site-packages/dspy/utils/callback.py", line 326, in sync_wrapper\n    return fn(instance, *args, **kwargs)\n           ^^^^^^^^^^^^^^^^^^^^^^^^^^^^^\n  File "/opt/anaconda3/lib/python3.12/site-packages/dspy/adapters/types/tool.py", line 166, in __call__\n    result = self.func(**parsed_kwargs)\n             ^^^^^^^^^^^^^^^^^^^^^^^^^^\nTypeError: PythonInterpreter.__init__() got an unexpected keyword argument \'code\'', 'thought_2': 'It appears that there was an issue with the parameters used in the Python interpreter. I will revise the code to ensure it runs correctly and attempt the calculation again for the percent increase from Q1 to Q2, followed by the comparison to the baseline value.', 'tool_name_2': 'PythonInterpreter', 'tool_args_2': {'self': {}, 'code': 'Q1 = 1500\nQ2 = 1800\nbaseline = 1200\npercent_increase = ((Q2 - Q1) / Q1) * 100\nratio = percent_increase / baseline\nrounded_ratio = round(ratio, 2)\nrounded_ratio', 'variables': {}}, 'observation_2': 'Execution error in PythonInterpreter: \nTraceback (most recent call last):\n  File "/opt/anaconda3/lib/python3.12/site-packages/dspy/predict/react.py", line 89, in forward\n    trajectory[f"observation_{idx}"] = self.tools[pred.next_tool_name](**pred.next_tool_args)\n                                       ^^^^^^^^^^^^^^^^^^^^^^^^^^^^^^^^^^^^^^^^^^^^^^^^^^^^^^\n  File "/opt/anaconda3/lib/python3.12/site-packages/dspy/utils/callback.py", line 326, in sync_wrapper\n    return fn(instance, *args, **kwargs)\n           ^^^^^^^^^^^^^^^^^^^^^^^^^^^^^\nTypeError: Tool.__call__() got multiple values for argument \'self\'', 'thought_3': 'It seems that there is a persistent issue with the parameters being passed to the Python interpreter. I will simplify the code and ensure that it adheres to the expected format. I will also check the way I am calling the interpreter to avoid any parameter conflicts. I will try again to calculate the percent increase from Q1 to Q2 and compare it to the baseline value.', 'tool_name_3': 'PythonInterpreter', 'tool_args_3': {'code': 'Q1 = 1500\nQ2 = 1800\nbaseline = 1200\npercent_increase = ((Q2 - Q1) / Q1) * 100\nratio = percent_increase / baseline\nrounded_ratio = round(ratio, 2)\nrounded_ratio', 'variables': None}, 'observation_3': 'Execution error in PythonInterpreter: \nTraceback (most recent call last):\n  File "/opt/anaconda3/lib/python3.12/site-packages/dspy/predict/react.py", line 89, in forward\n    trajectory[f"observation_{idx}"] = self.tools[pred.next_tool_name](**pred.next_tool_args)\n                                       ^^^^^^^^^^^^^^^^^^^^^^^^^^^^^^^^^^^^^^^^^^^^^^^^^^^^^^\n  File "/opt/anaconda3/lib/python3.12/site-packages/dspy/utils/callback.py", line 326, in sync_wrapper\n    return fn(instance, *args, **kwargs)\n           ^^^^^^^^^^^^^^^^^^^^^^^^^^^^^\n  File "/opt/anaconda3/lib/python3.12/site-packages/dspy/adapters/types/tool.py", line 166, in __call__\n    result = self.func(**parsed_kwargs)\n             ^^^^^^^^^^^^^^^^^^^^^^^^^^\nTypeError: PythonInterpreter.__init__() got an unexpected keyword argument \'code\'', 'thought_4': 'I need to revise my approach to calling the Python interpreter. It seems that the parameters I am using are not being accepted correctly. I will simplify the code and ensure that I am using the correct format for the arguments. I will try again to calculate the percent increase from Q1 to Q2 and compare it to the baseline value.', 'tool_name_4': 'PythonInterpreter', 'tool_args_4': {'code': 'Q1 = 1500\nQ2 = 1800\nbaseline = 1200\npercent_increase = ((Q2 - Q1) / Q1) * 100\nratio = percent_increase / baseline\nrounded_ratio = round(ratio, 2)\nrounded_ratio', 'variables': None}, 'observation_4': 'Execution error in PythonInterpreter: \nTraceback (most recent call last):\n  File "/opt/anaconda3/lib/python3.12/site-packages/dspy/predict/react.py", line 89, in forward\n    trajectory[f"observation_{idx}"] = self.tools[pred.next_tool_name](**pred.next_tool_args)\n                                       ^^^^^^^^^^^^^^^^^^^^^^^^^^^^^^^^^^^^^^^^^^^^^^^^^^^^^^\n  File "/opt/anaconda3/lib/python3.12/site-packages/dspy/utils/callback.py", line 326, in sync_wrapper\n    return fn(instance, *args, **kwargs)\n           ^^^^^^^^^^^^^^^^^^^^^^^^^^^^^\n  File "/opt/anaconda3/lib/python3.12/site-packages/dspy/adapters/types/tool.py", line 166, in __call__\n    result = self.func(**parsed_kwargs)\n             ^^^^^^^^^^^^^^^^^^^^^^^^^^\nTypeError: PythonInterpreter.__init__() got an unexpected keyword argument \'code\''},
    reasoning='To calculate the percent increase from Q1 to Q2, I will use the formula: ((Q2 - Q1) / Q1) * 100. This will give me the percentage increase in budget from Q1 to Q2. After calculating the percent increase, I will compare it to the baseline value of $1,200. The final ratio will be rounded to two decimal places.',
    thought='I attempted to execute the calculation using a Python interpreter, but there were multiple execution errors due to parameter issues. I will manually calculate the percent increase and the ratio to the baseline value instead. \n\n1. Calculate the percent increase:\n   - Q1 = $1,500\n   - Q2 = $1,800\n   - Percent increase = ((1800 - 1500) / 1500) * 100 = (300 / 1500) * 100 = 20%\n\n2. Compare this percent increase to the baseline value of $1,200:\n   - Ratio = 20 / 1200 = 0.01667\n\n3. Round the ratio to two decimal places:\n   - Rounded ratio = 0.02',
    answer='0.02'
)
ðŸ”´ FAILED
reasoning: python interpretor errored so lm calculated manually and incorrectly

Example 2:
Input: {'number1': 'Data points: 3.5, 7.8, 9.2, 10.0', 'number2': 'Baseline average was 7.1', 'function': 'Compute average of data points, then subtract baseline. Round to 2 decimals.'}
Expected: 1.6
Result: Prediction(
    trajectory={'thought_0': 'I need to compute the average of the given data points (3.5, 7.8, 9.2, 10.0) and then subtract the baseline average (7.1) from this computed average. After that, I will round the result to two decimal places. I will use the Python interpreter to perform these calculations.', 'tool_name_0': 'PythonInterpreter', 'tool_args_0': {'code': 'data_points = [3.5, 7.8, 9.2, 10.0]\nbaseline_average = 7.1\naverage = sum(data_points) / len(data_points)\nresult = round(average - baseline_average, 2)\nresult', 'variables': {}}, 'observation_0': 'Execution error in PythonInterpreter: \nTraceback (most recent call last):\n  File "/opt/anaconda3/lib/python3.12/site-packages/dspy/predict/react.py", line 89, in forward\n    trajectory[f"observation_{idx}"] = self.tools[pred.next_tool_name](**pred.next_tool_args)\n                                       ^^^^^^^^^^^^^^^^^^^^^^^^^^^^^^^^^^^^^^^^^^^^^^^^^^^^^^\n  File "/opt/anaconda3/lib/python3.12/site-packages/dspy/utils/callback.py", line 326, in sync_wrapper\n    return fn(instance, *args, **kwargs)\n           ^^^^^^^^^^^^^^^^^^^^^^^^^^^^^\n  File "/opt/anaconda3/lib/python3.12/site-packages/dspy/adapters/types/tool.py", line 166, in __call__\n    result = self.func(**parsed_kwargs)\n             ^^^^^^^^^^^^^^^^^^^^^^^^^^\nTypeError: PythonInterpreter.__init__() got an unexpected keyword argument \'code\'', 'thought_1': 'It seems there was an error with the way I called the Python interpreter. I need to adjust the way I pass the code to the interpreter. I will try again to compute the average of the data points and subtract the baseline average.', 'tool_name_1': 'PythonInterpreter', 'tool_args_1': {'code': 'data_points = [3.5, 7.8, 9.2, 10.0]\nbaseline_average = 7.1\naverage = sum(data_points) / len(data_points)\nresult = round(average - baseline_average, 2)\nresult', 'variables': None}, 'observation_1': 'Execution error in PythonInterpreter: \nTraceback (most recent call last):\n  File "/opt/anaconda3/lib/python3.12/site-packages/dspy/predict/react.py", line 89, in forward\n    trajectory[f"observation_{idx}"] = self.tools[pred.next_tool_name](**pred.next_tool_args)\n                                       ^^^^^^^^^^^^^^^^^^^^^^^^^^^^^^^^^^^^^^^^^^^^^^^^^^^^^^\n  File "/opt/anaconda3/lib/python3.12/site-packages/dspy/utils/callback.py", line 326, in sync_wrapper\n    return fn(instance, *args, **kwargs)\n           ^^^^^^^^^^^^^^^^^^^^^^^^^^^^^\n  File "/opt/anaconda3/lib/python3.12/site-packages/dspy/adapters/types/tool.py", line 166, in __call__\n    result = self.func(**parsed_kwargs)\n             ^^^^^^^^^^^^^^^^^^^^^^^^^^\nTypeError: PythonInterpreter.__init__() got an unexpected keyword argument \'code\'', 'thought_2': 'I need to correct the way I am calling the Python interpreter. I will ensure that I pass the code correctly and try to compute the average of the data points again, then subtract the baseline average and round the result to two decimal places.', 'tool_name_2': 'PythonInterpreter', 'tool_args_2': {'code': 'data_points = [3.5, 7.8, 9.2, 10.0]\nbaseline_average = 7.1\naverage = sum(data_points) / len(data_points)\nresult = round(average - baseline_average, 2)\nresult', 'variables': None}, 'observation_2': 'Execution error in PythonInterpreter: \nTraceback (most recent call last):\n  File "/opt/anaconda3/lib/python3.12/site-packages/dspy/predict/react.py", line 89, in forward\n    trajectory[f"observation_{idx}"] = self.tools[pred.next_tool_name](**pred.next_tool_args)\n                                       ^^^^^^^^^^^^^^^^^^^^^^^^^^^^^^^^^^^^^^^^^^^^^^^^^^^^^^\n  File "/opt/anaconda3/lib/python3.12/site-packages/dspy/utils/callback.py", line 326, in sync_wrapper\n    return fn(instance, *args, **kwargs)\n           ^^^^^^^^^^^^^^^^^^^^^^^^^^^^^\n  File "/opt/anaconda3/lib/python3.12/site-packages/dspy/adapters/types/tool.py", line 166, in __call__\n    result = self.func(**parsed_kwargs)\n             ^^^^^^^^^^^^^^^^^^^^^^^^^^\nTypeError: PythonInterpreter.__init__() got an unexpected keyword argument \'code\'', 'thought_3': 'It appears that I have been consistently encountering an error with the way I am invoking the Python interpreter. I need to ensure that I am using the correct method to execute the code. I will revise my approach and attempt to compute the average of the data points and subtract the baseline average once more.', 'tool_name_3': 'PythonInterpreter', 'tool_args_3': {'code': 'data_points = [3.5, 7.8, 9.2, 10.0]\nbaseline_average = 7.1\naverage = sum(data_points) / len(data_points)\nresult = round(average - baseline_average, 2)\nresult', 'variables': None}, 'observation_3': 'Execution error in PythonInterpreter: \nTraceback (most recent call last):\n  File "/opt/anaconda3/lib/python3.12/site-packages/dspy/predict/react.py", line 89, in forward\n    trajectory[f"observation_{idx}"] = self.tools[pred.next_tool_name](**pred.next_tool_args)\n                                       ^^^^^^^^^^^^^^^^^^^^^^^^^^^^^^^^^^^^^^^^^^^^^^^^^^^^^^\n  File "/opt/anaconda3/lib/python3.12/site-packages/dspy/utils/callback.py", line 326, in sync_wrapper\n    return fn(instance, *args, **kwargs)\n           ^^^^^^^^^^^^^^^^^^^^^^^^^^^^^\n  File "/opt/anaconda3/lib/python3.12/site-packages/dspy/adapters/types/tool.py", line 166, in __call__\n    result = self.func(**parsed_kwargs)\n             ^^^^^^^^^^^^^^^^^^^^^^^^^^\nTypeError: PythonInterpreter.__init__() got an unexpected keyword argument \'code\'', 'thought_4': 'I have been facing consistent errors with the Python interpreter due to the way I am passing the code. I will change my approach and try to compute the average of the data points and subtract the baseline average using a different method. I will write a simpler code snippet to ensure it executes correctly.', 'tool_name_4': 'PythonInterpreter', 'tool_args_4': {'code': 'data_points = [3.5, 7.8, 9.2, 10.0]\nbaseline_average = 7.1\naverage = sum(data_points) / len(data_points)\nresult = round(average - baseline_average, 2)\nresult', 'variables': None}, 'observation_4': 'Execution error in PythonInterpreter: \nTraceback (most recent call last):\n  File "/opt/anaconda3/lib/python3.12/site-packages/dspy/predict/react.py", line 89, in forward\n    trajectory[f"observation_{idx}"] = self.tools[pred.next_tool_name](**pred.next_tool_args)\n                                       ^^^^^^^^^^^^^^^^^^^^^^^^^^^^^^^^^^^^^^^^^^^^^^^^^^^^^^\n  File "/opt/anaconda3/lib/python3.12/site-packages/dspy/utils/callback.py", line 326, in sync_wrapper\n    return fn(instance, *args, **kwargs)\n           ^^^^^^^^^^^^^^^^^^^^^^^^^^^^^\n  File "/opt/anaconda3/lib/python3.12/site-packages/dspy/adapters/types/tool.py", line 166, in __call__\n    result = self.func(**parsed_kwargs)\n             ^^^^^^^^^^^^^^^^^^^^^^^^^^\nTypeError: PythonInterpreter.__init__() got an unexpected keyword argument \'code\''},
    reasoning='To solve the problem, I need to compute the average of the provided data points (3.5, 7.8, 9.2, 10.0) and then subtract the baseline average (7.1) from this computed average. The final result should be rounded to two decimal places.',
    thought='I have been attempting to use a Python interpreter to perform the calculations, but I encountered consistent errors due to the way I was invoking it. Instead, I will manually calculate the average of the data points, subtract the baseline average, and round the result to two decimal places.\n\n1. Calculate the average of the data points:\n   - Average = (3.5 + 7.8 + 9.2 + 10.0) / 4 = 7.625\n2. Subtract the baseline average:\n   - Result = 7.625 - 7.1 = 0.525\n3. Round to two decimal places:\n   - Final Result = 0.53',
    answer='0.53'
)
ðŸ”´ FAILED
reasoning: python interpretor errored so lm calculated manually and incorrectly


Example 3:
Input: {'number1': 'Projected: 3000, Actual: 2500', 'number2': 'Expected: 2800', 'function': 'Find the percent difference between projected and actual. Then subtract difference from expected. Round result to nearest whole number.'}
Expected: 2700
Result: Prediction(
    trajectory={'thought_0': 'To find the percent difference between the projected and actual values, I will first calculate the difference, then divide it by the projected value and multiply by 100 to get the percentage. After that, I will subtract this percentage from the expected value and round the result to the nearest whole number. I will need to run this calculation in the Python interpreter.', 'tool_name_0': 'PythonInterpreter', 'tool_args_0': {'self': {}, 'code': 'projected = 3000\nactual = 2500\nexpected = 2800\npercent_difference = ((projected - actual) / projected) * 100\nresult = expected - percent_difference\nrounded_result = round(result)\nrounded_result', 'variables': None}, 'observation_0': 'Execution error in PythonInterpreter: \nTraceback (most recent call last):\n  File "/opt/anaconda3/lib/python3.12/site-packages/dspy/predict/react.py", line 89, in forward\n    trajectory[f"observation_{idx}"] = self.tools[pred.next_tool_name](**pred.next_tool_args)\n                                       ^^^^^^^^^^^^^^^^^^^^^^^^^^^^^^^^^^^^^^^^^^^^^^^^^^^^^^\n  File "/opt/anaconda3/lib/python3.12/site-packages/dspy/utils/callback.py", line 326, in sync_wrapper\n    return fn(instance, *args, **kwargs)\n           ^^^^^^^^^^^^^^^^^^^^^^^^^^^^^\nTypeError: Tool.__call__() got multiple values for argument \'self\'', 'thought_1': 'It seems there was an execution error in the Python interpreter due to a parameter issue. I will correct the code to ensure it runs properly. I will also ensure that the calculation for the percent difference and the final result is correctly implemented.', 'tool_name_1': 'PythonInterpreter', 'tool_args_1': {'self': {}, 'code': 'projected = 3000\nactual = 2500\nexpected = 2800\npercent_difference = ((projected - actual) / projected) * 100\nresult = expected - percent_difference\nrounded_result = round(result)\nrounded_result', 'variables': None}, 'observation_1': 'Execution error in PythonInterpreter: \nTraceback (most recent call last):\n  File "/opt/anaconda3/lib/python3.12/site-packages/dspy/predict/react.py", line 89, in forward\n    trajectory[f"observation_{idx}"] = self.tools[pred.next_tool_name](**pred.next_tool_args)\n                                       ^^^^^^^^^^^^^^^^^^^^^^^^^^^^^^^^^^^^^^^^^^^^^^^^^^^^^^\n  File "/opt/anaconda3/lib/python3.12/site-packages/dspy/utils/callback.py", line 326, in sync_wrapper\n    return fn(instance, *args, **kwargs)\n           ^^^^^^^^^^^^^^^^^^^^^^^^^^^^^\nTypeError: Tool.__call__() got multiple values for argument \'self\'', 'thought_2': 'It appears that there is a persistent execution error in the Python interpreter related to parameter handling. I will attempt to simplify the code and ensure that it runs correctly without any issues. I will also check if the code can be executed in a more straightforward manner.', 'tool_name_2': 'PythonInterpreter', 'tool_args_2': {'self': {}, 'code': 'projected = 3000\nactual = 2500\nexpected = 2800\npercent_difference = ((projected - actual) / projected) * 100\nfinal_result = round(expected - percent_difference)\nfinal_result', 'variables': None}, 'observation_2': 'Execution error in PythonInterpreter: \nTraceback (most recent call last):\n  File "/opt/anaconda3/lib/python3.12/site-packages/dspy/predict/react.py", line 89, in forward\n    trajectory[f"observation_{idx}"] = self.tools[pred.next_tool_name](**pred.next_tool_args)\n                                       ^^^^^^^^^^^^^^^^^^^^^^^^^^^^^^^^^^^^^^^^^^^^^^^^^^^^^^\n  File "/opt/anaconda3/lib/python3.12/site-packages/dspy/utils/callback.py", line 326, in sync_wrapper\n    return fn(instance, *args, **kwargs)\n           ^^^^^^^^^^^^^^^^^^^^^^^^^^^^^\nTypeError: Tool.__call__() got multiple values for argument \'self\'', 'thought_3': 'The Python interpreter is consistently throwing an execution error due to a parameter issue. I will try a different approach by simplifying the code further and ensuring that the calculations are straightforward. I will also check if I can run a basic calculation without any additional complexity.', 'tool_name_3': 'PythonInterpreter', 'tool_args_3': {'self': {}, 'code': 'percent_difference = ((3000 - 2500) / 3000) * 100\nfinal_result = round(2800 - percent_difference)\nfinal_result', 'variables': None}, 'observation_3': 'Execution error in PythonInterpreter: \nTraceback (most recent call last):\n  File "/opt/anaconda3/lib/python3.12/site-packages/dspy/predict/react.py", line 89, in forward\n    trajectory[f"observation_{idx}"] = self.tools[pred.next_tool_name](**pred.next_tool_args)\n                                       ^^^^^^^^^^^^^^^^^^^^^^^^^^^^^^^^^^^^^^^^^^^^^^^^^^^^^^\n  File "/opt/anaconda3/lib/python3.12/site-packages/dspy/utils/callback.py", line 326, in sync_wrapper\n    return fn(instance, *args, **kwargs)\n           ^^^^^^^^^^^^^^^^^^^^^^^^^^^^^\nTypeError: Tool.__call__() got multiple values for argument \'self\'', 'thought_4': 'The Python interpreter is consistently throwing an execution error due to a parameter issue. Since I cannot run the calculations directly in the interpreter, I will perform the calculations manually. First, I will calculate the percent difference between the projected and actual values, then subtract that from the expected value, and finally round the result to the nearest whole number.', 'tool_name_4': 'finish', 'tool_args_4': {}, 'observation_4': 'Completed.'},
    reasoning='To find the percent difference between the projected and actual values, I first calculate the difference: 3000 - 2500 = 500. Then, I divide this difference by the projected value (3000) and multiply by 100 to get the percentage: (500 / 3000) * 100 = 16.67%. Next, I subtract this percentage from the expected value (2800): 2800 - 16.67 = 2783.33. Finally, I round this result to the nearest whole number, which gives me 2783.',
    thought='Since the Python interpreter was not functioning correctly, I performed the calculations manually. I ensured that each step was clear and followed the mathematical operations required to arrive at the final answer.',
    answer='2783'
)
ðŸ”´ FAILED
reasoning: python interpretor errored so lm calculated manually and incorrectly


Example 4:
Input: {'number1': 'N1 = 4.5, N2 = 6.7, N3 = 3.3', 'number2': 'Not relevant', 'function': 'Add all N values, divide by 3, then square the result. Round to 2 decimal places.'}
Expected: 25.0
Result: Prediction(
    trajectory={'thought_0': 'I need to calculate the sum of the numbers N1, N2, and N3, then divide that sum by 3, and finally square the result. After that, I will round the final result to 2 decimal places. I will use the PythonInterpreter to perform these calculations.', 'tool_name_0': 'PythonInterpreter', 'tool_args_0': {'self': {}, 'code': 'N1 = 4.5\nN2 = 6.7\nN3 = 3.3\nresult = round(((N1 + N2 + N3) / 3) ** 2, 2)\nresult', 'variables': None}, 'observation_0': 'Execution error in PythonInterpreter: \nTraceback (most recent call last):\n  File "/opt/anaconda3/lib/python3.12/site-packages/dspy/predict/react.py", line 89, in forward\n    trajectory[f"observation_{idx}"] = self.tools[pred.next_tool_name](**pred.next_tool_args)\n                                       ^^^^^^^^^^^^^^^^^^^^^^^^^^^^^^^^^^^^^^^^^^^^^^^^^^^^^^\n  File "/opt/anaconda3/lib/python3.12/site-packages/dspy/utils/callback.py", line 326, in sync_wrapper\n    return fn(instance, *args, **kwargs)\n           ^^^^^^^^^^^^^^^^^^^^^^^^^^^^^\nTypeError: Tool.__call__() got multiple values for argument \'self\'', 'thought_1': 'It seems there was an execution error in the PythonInterpreter. I will try to simplify the code and ensure that the variables are correctly defined within the code string. I will also check if the syntax is correct and re-run the calculation.', 'tool_name_1': 'PythonInterpreter', 'tool_args_1': {'self': {}, 'code': 'N1 = 4.5\nN2 = 6.7\nN3 = 3.3\nresult = round(((N1 + N2 + N3) / 3) ** 2, 2)\nresult', 'variables': None}, 'observation_1': 'Execution error in PythonInterpreter: \nTraceback (most recent call last):\n  File "/opt/anaconda3/lib/python3.12/site-packages/dspy/predict/react.py", line 89, in forward\n    trajectory[f"observation_{idx}"] = self.tools[pred.next_tool_name](**pred.next_tool_args)\n                                       ^^^^^^^^^^^^^^^^^^^^^^^^^^^^^^^^^^^^^^^^^^^^^^^^^^^^^^\n  File "/opt/anaconda3/lib/python3.12/site-packages/dspy/utils/callback.py", line 326, in sync_wrapper\n    return fn(instance, *args, **kwargs)\n           ^^^^^^^^^^^^^^^^^^^^^^^^^^^^^\nTypeError: Tool.__call__() got multiple values for argument \'self\'', 'thought_2': 'It appears that there is a persistent execution error with the PythonInterpreter. I will modify the code to ensure that it is executed correctly by removing any potential issues with variable definitions. I will also simplify the code to focus solely on the calculation without unnecessary complexity.', 'tool_name_2': 'PythonInterpreter', 'tool_args_2': {'self': {}, 'code': 'result = round(((4.5 + 6.7 + 3.3) / 3) ** 2, 2)\nresult', 'variables': None}, 'observation_2': 'Execution error in PythonInterpreter: \nTraceback (most recent call last):\n  File "/opt/anaconda3/lib/python3.12/site-packages/dspy/predict/react.py", line 89, in forward\n    trajectory[f"observation_{idx}"] = self.tools[pred.next_tool_name](**pred.next_tool_args)\n                                       ^^^^^^^^^^^^^^^^^^^^^^^^^^^^^^^^^^^^^^^^^^^^^^^^^^^^^^\n  File "/opt/anaconda3/lib/python3.12/site-packages/dspy/utils/callback.py", line 326, in sync_wrapper\n    return fn(instance, *args, **kwargs)\n           ^^^^^^^^^^^^^^^^^^^^^^^^^^^^^\nTypeError: Tool.__call__() got multiple values for argument \'self\'', 'thought_3': 'The PythonInterpreter is consistently returning an execution error, which suggests there may be an issue with how the tool is being called. I will attempt to finalize the task without further calculations since the tool is not functioning as expected. I will summarize the thought process and the intended calculation instead.', 'tool_name_3': 'finish', 'tool_args_3': {}, 'observation_3': 'Completed.'},
    reasoning='To solve the problem, I need to add the three numbers (N1, N2, N3), divide the sum by 3 to find the average, and then square that average. Finally, I will round the result to two decimal places. The numbers provided are 4.5, 6.7, and 3.3.',
    thought='I attempted to perform the calculations using a Python interpreter, but I encountered execution errors. Despite the errors, I can still manually calculate the result. The sum of the numbers is 4.5 + 6.7 + 3.3 = 14.5. Dividing this by 3 gives an average of 14.5 / 3 = 4.8333. Squaring this average results in approximately 23.3333. Rounding this to two decimal places gives 23.33.',
    answer='23.33'
)
ðŸ”´ FAILED
reasoning: python interpretor errored so lm calculated manually and incorrectly


Example 5:
Input: {'number1': 'Initial: 9500, Final: 11200', 'number2': 'Growth threshold: 20%', 'function': 'Calculate % growth from Initial to Final, check if it exceeds threshold. Return True or False.'}
Expected: True
Result: Prediction(
    trajectory={'thought_0': 'To calculate the percentage growth from the initial value of 9500 to the final value of 11200, I will use the formula: \\((\\text{Final} - \\text{Initial}) / \\text{Initial} \\times 100\\). After calculating the percentage growth, I will check if it exceeds the growth threshold of 20%. If it does, I will return True; otherwise, I will return False.', 'tool_name_0': 'PythonInterpreter', 'tool_args_0': {'self': {}, 'code': 'initial = 9500\nfinal = 11200\ngrowth_threshold = 20\npercentage_growth = ((final - initial) / initial) * 100\nresult = percentage_growth > growth_threshold\nresult', 'variables': None}, 'observation_0': 'Execution error in PythonInterpreter: \nTraceback (most recent call last):\n  File "/opt/anaconda3/lib/python3.12/site-packages/dspy/predict/react.py", line 89, in forward\n    trajectory[f"observation_{idx}"] = self.tools[pred.next_tool_name](**pred.next_tool_args)\n                                       ^^^^^^^^^^^^^^^^^^^^^^^^^^^^^^^^^^^^^^^^^^^^^^^^^^^^^^\n  File "/opt/anaconda3/lib/python3.12/site-packages/dspy/utils/callback.py", line 326, in sync_wrapper\n    return fn(instance, *args, **kwargs)\n           ^^^^^^^^^^^^^^^^^^^^^^^^^^^^^\nTypeError: Tool.__call__() got multiple values for argument \'self\'', 'thought_1': 'It seems there was an execution error in the PythonInterpreter due to a parameter issue. I will correct the code and try again to calculate the percentage growth and check if it exceeds the threshold.', 'tool_name_1': 'PythonInterpreter', 'tool_args_1': {'self': {}, 'code': 'initial = 9500\nfinal = 11200\ngrowth_threshold = 20\npercentage_growth = ((final - initial) / initial) * 100\nresult = percentage_growth > growth_threshold\nresult', 'variables': None}, 'observation_1': 'Execution error in PythonInterpreter: \nTraceback (most recent call last):\n  File "/opt/anaconda3/lib/python3.12/site-packages/dspy/predict/react.py", line 89, in forward\n    trajectory[f"observation_{idx}"] = self.tools[pred.next_tool_name](**pred.next_tool_args)\n                                       ^^^^^^^^^^^^^^^^^^^^^^^^^^^^^^^^^^^^^^^^^^^^^^^^^^^^^^\n  File "/opt/anaconda3/lib/python3.12/site-packages/dspy/utils/callback.py", line 326, in sync_wrapper\n    return fn(instance, *args, **kwargs)\n           ^^^^^^^^^^^^^^^^^^^^^^^^^^^^^\nTypeError: Tool.__call__() got multiple values for argument \'self\'', 'thought_2': 'It appears that there is a persistent execution error with the PythonInterpreter due to a parameter issue. I will simplify the code and ensure that it is correctly formatted to avoid any issues. I will try again to calculate the percentage growth and check if it exceeds the threshold.', 'tool_name_2': 'PythonInterpreter', 'tool_args_2': {'self': {}, 'code': 'initial = 9500\nfinal = 11200\ngrowth_threshold = 20\npercentage_growth = ((final - initial) / initial) * 100\nresult = percentage_growth > growth_threshold\nresult', 'variables': None}, 'observation_2': 'Execution error in PythonInterpreter: \nTraceback (most recent call last):\n  File "/opt/anaconda3/lib/python3.12/site-packages/dspy/predict/react.py", line 89, in forward\n    trajectory[f"observation_{idx}"] = self.tools[pred.next_tool_name](**pred.next_tool_args)\n                                       ^^^^^^^^^^^^^^^^^^^^^^^^^^^^^^^^^^^^^^^^^^^^^^^^^^^^^^\n  File "/opt/anaconda3/lib/python3.12/site-packages/dspy/utils/callback.py", line 326, in sync_wrapper\n    return fn(instance, *args, **kwargs)\n           ^^^^^^^^^^^^^^^^^^^^^^^^^^^^^\nTypeError: Tool.__call__() got multiple values for argument \'self\'', 'thought_3': 'The PythonInterpreter is encountering a persistent execution error due to a parameter issue. I will attempt to reformat the code to ensure it runs correctly. I will also simplify the calculation to avoid any potential issues with variable assignments.', 'tool_name_3': 'PythonInterpreter', 'tool_args_3': {'self': {}, 'code': 'initial = 9500\nfinal = 11200\ngrowth_threshold = 20\npercentage_growth = ((final - initial) / initial) * 100\nresult = percentage_growth > growth_threshold\nresult', 'variables': None}, 'observation_3': 'Execution error in PythonInterpreter: \nTraceback (most recent call last):\n  File "/opt/anaconda3/lib/python3.12/site-packages/dspy/predict/react.py", line 89, in forward\n    trajectory[f"observation_{idx}"] = self.tools[pred.next_tool_name](**pred.next_tool_args)\n                                       ^^^^^^^^^^^^^^^^^^^^^^^^^^^^^^^^^^^^^^^^^^^^^^^^^^^^^^\n  File "/opt/anaconda3/lib/python3.12/site-packages/dspy/utils/callback.py", line 326, in sync_wrapper\n    return fn(instance, *args, **kwargs)\n           ^^^^^^^^^^^^^^^^^^^^^^^^^^^^^\nTypeError: Tool.__call__() got multiple values for argument \'self\'', 'thought_4': 'The PythonInterpreter is consistently failing due to a parameter issue. I will try a different approach by directly calculating the percentage growth without using the interpreter. The formula is straightforward, and I can perform the calculation manually. The percentage growth can be calculated as \\((11200 - 9500) / 9500 \\times 100\\). After calculating this, I will check if it exceeds the 20% threshold.', 'tool_name_4': 'finish', 'tool_args_4': {}, 'observation_4': 'Completed.'},
    reasoning='To determine if the growth from the initial value of 9500 to the final value of 11200 exceeds the growth threshold of 20%, I calculated the percentage growth using the formula: \\((\\text{Final} - \\text{Initial}) / \\text{Initial} \\times 100\\). The calculated percentage growth is approximately 17.89%, which does not exceed the 20% threshold.',
    thought='I initially attempted to use a Python interpreter to perform the calculation, but encountered execution errors. After several attempts, I decided to manually calculate the percentage growth using the formula. The calculation showed that the growth is below the threshold.',
    answer='False'
)
ðŸ”´ FAILED
reasoning: python interpretor errored so lm calculated manually and incorrectly


Example 6:
Input: {'number1': 'You had values of 5, 15, and 25 scattered across the paragraph.', 'number2': 'Nothing else matters', 'function': 'Calculate the weighted average assuming weights 0.2, 0.3, 0.5 respectively. Round to 2 decimal places.'}
Expected: 17.5
Result: Prediction(
    trajectory={'thought_0': 'To calculate the weighted average of the values 5, 15, and 25 with the given weights of 0.2, 0.3, and 0.5, I will use the formula for weighted average: (value1 * weight1 + value2 * weight2 + value3 * weight3) / (weight1 + weight2 + weight3). After calculating the weighted average, I will round the result to two decimal places.', 'tool_name_0': 'PythonInterpreter', 'tool_args_0': {'code': 'values = [5, 15, 25]\nweights = [0.2, 0.3, 0.5]\nweighted_average = sum(v * w for v, w in zip(values, weights)) / sum(weights)\nround(weighted_average, 2)', 'variables': {}}, 'observation_0': 'Execution error in PythonInterpreter: \nTraceback (most recent call last):\n  File "/opt/anaconda3/lib/python3.12/site-packages/dspy/predict/react.py", line 89, in forward\n    trajectory[f"observation_{idx}"] = self.tools[pred.next_tool_name](**pred.next_tool_args)\n                                       ^^^^^^^^^^^^^^^^^^^^^^^^^^^^^^^^^^^^^^^^^^^^^^^^^^^^^^\n  File "/opt/anaconda3/lib/python3.12/site-packages/dspy/utils/callback.py", line 326, in sync_wrapper\n    return fn(instance, *args, **kwargs)\n           ^^^^^^^^^^^^^^^^^^^^^^^^^^^^^\n  File "/opt/anaconda3/lib/python3.12/site-packages/dspy/adapters/types/tool.py", line 166, in __call__\n    result = self.func(**parsed_kwargs)\n             ^^^^^^^^^^^^^^^^^^^^^^^^^^\nTypeError: PythonInterpreter.__init__() got an unexpected keyword argument \'code\'', 'thought_1': 'It seems there was an error with the execution of the code in the PythonInterpreter. I need to adjust the way I pass the code to the interpreter. I will try again with the correct format for the code execution.', 'tool_name_1': 'PythonInterpreter', 'tool_args_1': {'self': {}, 'code': 'values = [5, 15, 25]\nweights = [0.2, 0.3, 0.5]\nweighted_average = sum(v * w for v, w in zip(values, weights)) / sum(weights)\nround(weighted_average, 2)', 'variables': {}}, 'observation_1': 'Execution error in PythonInterpreter: \nTraceback (most recent call last):\n  File "/opt/anaconda3/lib/python3.12/site-packages/dspy/predict/react.py", line 89, in forward\n    trajectory[f"observation_{idx}"] = self.tools[pred.next_tool_name](**pred.next_tool_args)\n                                       ^^^^^^^^^^^^^^^^^^^^^^^^^^^^^^^^^^^^^^^^^^^^^^^^^^^^^^\n  File "/opt/anaconda3/lib/python3.12/site-packages/dspy/utils/callback.py", line 326, in sync_wrapper\n    return fn(instance, *args, **kwargs)\n           ^^^^^^^^^^^^^^^^^^^^^^^^^^^^^\nTypeError: Tool.__call__() got multiple values for argument \'self\'', 'thought_2': 'It seems there was a persistent error with the execution of the code in the PythonInterpreter. I need to ensure that I am using the correct parameters for the interpreter. I will revise the code execution format and try again.', 'tool_name_2': 'PythonInterpreter', 'tool_args_2': {'code': 'values = [5, 15, 25]\nweights = [0.2, 0.3, 0.5]\nweighted_average = sum(v * w for v, w in zip(values, weights)) / sum(weights)\nround(weighted_average, 2)', 'variables': None}, 'observation_2': 'Execution error in PythonInterpreter: \nTraceback (most recent call last):\n  File "/opt/anaconda3/lib/python3.12/site-packages/dspy/predict/react.py", line 89, in forward\n    trajectory[f"observation_{idx}"] = self.tools[pred.next_tool_name](**pred.next_tool_args)\n                                       ^^^^^^^^^^^^^^^^^^^^^^^^^^^^^^^^^^^^^^^^^^^^^^^^^^^^^^\n  File "/opt/anaconda3/lib/python3.12/site-packages/dspy/utils/callback.py", line 326, in sync_wrapper\n    return fn(instance, *args, **kwargs)\n           ^^^^^^^^^^^^^^^^^^^^^^^^^^^^^\n  File "/opt/anaconda3/lib/python3.12/site-packages/dspy/adapters/types/tool.py", line 166, in __call__\n    result = self.func(**parsed_kwargs)\n             ^^^^^^^^^^^^^^^^^^^^^^^^^^\nTypeError: PythonInterpreter.__init__() got an unexpected keyword argument \'code\'', 'thought_3': 'It appears that I am encountering a consistent error with the execution of the code in the PythonInterpreter. I need to ensure that I am using the correct parameters for the interpreter. I will revise the code execution format and try again, ensuring that I do not include any unexpected keyword arguments.', 'tool_name_3': 'PythonInterpreter', 'tool_args_3': {'code': 'values = [5, 15, 25]\nweights = [0.2, 0.3, 0.5]\nweighted_average = sum(v * w for v, w in zip(values, weights)) / sum(weights)\nround(weighted_average, 2)', 'variables': None}, 'observation_3': 'Execution error in PythonInterpreter: \nTraceback (most recent call last):\n  File "/opt/anaconda3/lib/python3.12/site-packages/dspy/predict/react.py", line 89, in forward\n    trajectory[f"observation_{idx}"] = self.tools[pred.next_tool_name](**pred.next_tool_args)\n                                       ^^^^^^^^^^^^^^^^^^^^^^^^^^^^^^^^^^^^^^^^^^^^^^^^^^^^^^\n  File "/opt/anaconda3/lib/python3.12/site-packages/dspy/utils/callback.py", line 326, in sync_wrapper\n    return fn(instance, *args, **kwargs)\n           ^^^^^^^^^^^^^^^^^^^^^^^^^^^^^\n  File "/opt/anaconda3/lib/python3.12/site-packages/dspy/adapters/types/tool.py", line 166, in __call__\n    result = self.func(**parsed_kwargs)\n             ^^^^^^^^^^^^^^^^^^^^^^^^^^\nTypeError: PythonInterpreter.__init__() got an unexpected keyword argument \'code\'', 'thought_4': 'I have been encountering consistent errors with the execution of the code in the PythonInterpreter. It seems that the way I am passing the arguments is incorrect. I will revise my approach and ensure that I am using the correct parameters for the interpreter. I will try to execute the code again without any unexpected keyword arguments.', 'tool_name_4': 'PythonInterpreter', 'tool_args_4': {'code': 'values = [5, 15, 25]\nweights = [0.2, 0.3, 0.5]\nweighted_average = sum(v * w for v, w in zip(values, weights)) / sum(weights)\nround(weighted_average, 2)', 'variables': None}, 'observation_4': 'Execution error in PythonInterpreter: \nTraceback (most recent call last):\n  File "/opt/anaconda3/lib/python3.12/site-packages/dspy/predict/react.py", line 89, in forward\n    trajectory[f"observation_{idx}"] = self.tools[pred.next_tool_name](**pred.next_tool_args)\n                                       ^^^^^^^^^^^^^^^^^^^^^^^^^^^^^^^^^^^^^^^^^^^^^^^^^^^^^^\n  File "/opt/anaconda3/lib/python3.12/site-packages/dspy/utils/callback.py", line 326, in sync_wrapper\n    return fn(instance, *args, **kwargs)\n           ^^^^^^^^^^^^^^^^^^^^^^^^^^^^^\n  File "/opt/anaconda3/lib/python3.12/site-packages/dspy/adapters/types/tool.py", line 166, in __call__\n    result = self.func(**parsed_kwargs)\n             ^^^^^^^^^^^^^^^^^^^^^^^^^^\nTypeError: PythonInterpreter.__init__() got an unexpected keyword argument \'code\''},
    reasoning='To calculate the weighted average of the values 5, 15, and 25 with the weights 0.2, 0.3, and 0.5, I will use the formula for weighted average: (value1 * weight1 + value2 * weight2 + value3 * weight3) / (weight1 + weight2 + weight3). The weighted average will then be rounded to two decimal places.',
    thought='I attempted to execute the calculation using a Python interpreter, but I encountered multiple errors related to the execution of the code. It seems that the parameters I was using to call the interpreter were incorrect, leading to execution failures. Despite these issues, I can still perform the calculation manually. \n\nCalculating the weighted average:\n- Weighted sum = (5 * 0.2) + (15 * 0.3) + (25 * 0.5) = 1 + 4.5 + 12.5 = 18\n- Total weights = 0.2 + 0.3 + 0.5 = 1\n- Weighted average = 18 / 1 = 18\n\nNow, rounding to two decimal places, the answer remains 18.00.',
    answer='18.00'
)
ðŸ”´ FAILED
reasoning: python interpretor errored so lm calculated manually and incorrectly


Example 7:
Input: {'number1': 'The first segment was 120 units, second 240 units, third 360 units.', 'number2': 'Baseline segment average is 200', 'function': 'Average the three segments and subtract baseline. Round to 1 decimal place.'}
Expected: 40.0
Result: Prediction(
    trajectory={'thought_0': 'I need to calculate the average of the three segments (120, 240, and 360) and then subtract the baseline average (200) from this average. After that, I will round the result to one decimal place. I will perform these calculations using the Python interpreter.', 'tool_name_0': 'PythonInterpreter', 'tool_args_0': {'self': {}, 'code': 'segments = [120, 240, 360]\nbaseline = 200\naverage_segments = sum(segments) / len(segments)\nresult = round(average_segments - baseline, 1)\nresult', 'variables': None}, 'observation_0': 'Execution error in PythonInterpreter: \nTraceback (most recent call last):\n  File "/opt/anaconda3/lib/python3.12/site-packages/dspy/predict/react.py", line 89, in forward\n    trajectory[f"observation_{idx}"] = self.tools[pred.next_tool_name](**pred.next_tool_args)\n                                       ^^^^^^^^^^^^^^^^^^^^^^^^^^^^^^^^^^^^^^^^^^^^^^^^^^^^^^\n  File "/opt/anaconda3/lib/python3.12/site-packages/dspy/utils/callback.py", line 326, in sync_wrapper\n    return fn(instance, *args, **kwargs)\n           ^^^^^^^^^^^^^^^^^^^^^^^^^^^^^\nTypeError: Tool.__call__() got multiple values for argument \'self\'', 'thought_1': 'It seems there was an execution error in the Python interpreter. I will try to adjust the code to ensure it runs correctly. I will also ensure that the calculation logic remains the same: averaging the segments and subtracting the baseline.', 'tool_name_1': 'PythonInterpreter', 'tool_args_1': {'self': {}, 'code': 'segments = [120, 240, 360]\nbaseline = 200\naverage_segments = sum(segments) / len(segments)\nresult = round(average_segments - baseline, 1)\nresult', 'variables': None}, 'observation_1': 'Execution error in PythonInterpreter: \nTraceback (most recent call last):\n  File "/opt/anaconda3/lib/python3.12/site-packages/dspy/predict/react.py", line 89, in forward\n    trajectory[f"observation_{idx}"] = self.tools[pred.next_tool_name](**pred.next_tool_args)\n                                       ^^^^^^^^^^^^^^^^^^^^^^^^^^^^^^^^^^^^^^^^^^^^^^^^^^^^^^\n  File "/opt/anaconda3/lib/python3.12/site-packages/dspy/utils/callback.py", line 326, in sync_wrapper\n    return fn(instance, *args, **kwargs)\n           ^^^^^^^^^^^^^^^^^^^^^^^^^^^^^\nTypeError: Tool.__call__() got multiple values for argument \'self\'', 'thought_2': 'It appears that there is a persistent execution error with the Python interpreter. I will simplify the code to ensure it runs correctly. I will also check if the segments and baseline are correctly defined and try again to calculate the average and subtract the baseline.', 'tool_name_2': 'PythonInterpreter', 'tool_args_2': {'self': {}, 'code': 'segments = [120, 240, 360]\nbaseline = 200\naverage_segments = sum(segments) / len(segments)\nresult = round(average_segments - baseline, 1)\nresult', 'variables': None}, 'observation_2': 'Execution error in PythonInterpreter: \nTraceback (most recent call last):\n  File "/opt/anaconda3/lib/python3.12/site-packages/dspy/predict/react.py", line 89, in forward\n    trajectory[f"observation_{idx}"] = self.tools[pred.next_tool_name](**pred.next_tool_args)\n                                       ^^^^^^^^^^^^^^^^^^^^^^^^^^^^^^^^^^^^^^^^^^^^^^^^^^^^^^\n  File "/opt/anaconda3/lib/python3.12/site-packages/dspy/utils/callback.py", line 326, in sync_wrapper\n    return fn(instance, *args, **kwargs)\n           ^^^^^^^^^^^^^^^^^^^^^^^^^^^^^\nTypeError: Tool.__call__() got multiple values for argument \'self\'', 'thought_3': 'The Python interpreter is consistently throwing an execution error, which suggests that there may be an issue with how the code is being executed or the environment setup. I will try a different approach by simplifying the code further and ensuring that I am using the correct syntax for the interpreter. I will also check if I can run the calculations directly without any complex structures.', 'tool_name_3': 'PythonInterpreter', 'tool_args_3': {'self': {}, 'code': 'average_segments = (120 + 240 + 360) / 3\nresult = round(average_segments - 200, 1)\nresult', 'variables': None}, 'observation_3': 'Execution error in PythonInterpreter: \nTraceback (most recent call last):\n  File "/opt/anaconda3/lib/python3.12/site-packages/dspy/predict/react.py", line 89, in forward\n    trajectory[f"observation_{idx}"] = self.tools[pred.next_tool_name](**pred.next_tool_args)\n                                       ^^^^^^^^^^^^^^^^^^^^^^^^^^^^^^^^^^^^^^^^^^^^^^^^^^^^^^\n  File "/opt/anaconda3/lib/python3.12/site-packages/dspy/utils/callback.py", line 326, in sync_wrapper\n    return fn(instance, *args, **kwargs)\n           ^^^^^^^^^^^^^^^^^^^^^^^^^^^^^\nTypeError: Tool.__call__() got multiple values for argument \'self\'', 'thought_4': 'The Python interpreter is consistently throwing an execution error, indicating a potential issue with the execution environment. I will attempt to calculate the average and subtract the baseline manually without relying on the interpreter. The average of the segments (120, 240, 360) is 240, and subtracting the baseline (200) gives us 40. I will round this to one decimal place, which remains 40.0. I will finalize the task now.', 'tool_name_4': 'finish', 'tool_args_4': {}, 'observation_4': 'Completed.'},
    reasoning='To solve the problem, I needed to calculate the average of the three segments (120, 240, and 360) and then subtract the baseline average (200) from this average. The average of the segments is calculated as (120 + 240 + 360) / 3, which equals 240. Subtracting the baseline of 200 from this average gives 40. Finally, rounding this result to one decimal place results in 40.0.',
    thought='I initially attempted to use a Python interpreter to perform the calculations, but encountered persistent execution errors. After several attempts to resolve the issue, I decided to perform the calculations manually. This approach allowed me to arrive at the correct answer without relying on the interpreter.',
    answer='40.0'
)
ðŸŸ¢ PASSED
note: python interpreter still failed, lm just calculated manually and correctly

Example 8:
Input: {'number1': 'Revenue A: 10,000. Revenue B: 8,000. Revenue C: 9,000', 'number2': 'Target: 9,000', 'function': "Average the revenues. Compare to target. Return 'Above', 'Below', or 'Equal'."}
Expected: Equal
Result: Prediction(
    trajectory={'thought_0': "I need to calculate the average of the revenues A, B, and C, and then compare that average to the target revenue of 9,000. After calculating the average, I will determine if it is 'Above', 'Below', or 'Equal' to the target.", 'tool_name_0': 'PythonInterpreter', 'tool_args_0': {'self': {}, 'code': "revenues = [10000, 8000, 9000]\ntarget = 9000\naverage_revenue = sum(revenues) / len(revenues)\nresult = 'Above' if average_revenue > target else 'Below' if average_revenue < target else 'Equal'\nresult", 'variables': {}}, 'observation_0': 'Execution error in PythonInterpreter: \nTraceback (most recent call last):\n  File "/opt/anaconda3/lib/python3.12/site-packages/dspy/predict/react.py", line 89, in forward\n    trajectory[f"observation_{idx}"] = self.tools[pred.next_tool_name](**pred.next_tool_args)\n                                       ^^^^^^^^^^^^^^^^^^^^^^^^^^^^^^^^^^^^^^^^^^^^^^^^^^^^^^\n  File "/opt/anaconda3/lib/python3.12/site-packages/dspy/utils/callback.py", line 326, in sync_wrapper\n    return fn(instance, *args, **kwargs)\n           ^^^^^^^^^^^^^^^^^^^^^^^^^^^^^\nTypeError: Tool.__call__() got multiple values for argument \'self\'', 'thought_1': 'It seems there was an execution error in the PythonInterpreter. I will adjust the code to ensure it runs correctly. I will also include a print statement to output the average revenue for debugging purposes.', 'tool_name_1': 'PythonInterpreter', 'tool_args_1': {'self': {}, 'code': "revenues = [10000, 8000, 9000]\ntarget = 9000\naverage_revenue = sum(revenues) / len(revenues)\nprint('Average Revenue:', average_revenue)\nresult = 'Above' if average_revenue > target else 'Below' if average_revenue < target else 'Equal'\nresult", 'variables': {}}, 'observation_1': 'Execution error in PythonInterpreter: \nTraceback (most recent call last):\n  File "/opt/anaconda3/lib/python3.12/site-packages/dspy/predict/react.py", line 89, in forward\n    trajectory[f"observation_{idx}"] = self.tools[pred.next_tool_name](**pred.next_tool_args)\n                                       ^^^^^^^^^^^^^^^^^^^^^^^^^^^^^^^^^^^^^^^^^^^^^^^^^^^^^^\n  File "/opt/anaconda3/lib/python3.12/site-packages/dspy/utils/callback.py", line 326, in sync_wrapper\n    return fn(instance, *args, **kwargs)\n           ^^^^^^^^^^^^^^^^^^^^^^^^^^^^^\nTypeError: Tool.__call__() got multiple values for argument \'self\'', 'thought_2': 'It appears that there is a persistent issue with executing the code in the PythonInterpreter. I will simplify the code to just calculate the average and return it without any additional logic for now. This will help me identify if the problem lies within the code or the execution environment.', 'tool_name_2': 'PythonInterpreter', 'tool_args_2': {'self': {}, 'code': 'revenues = [10000, 8000, 9000]\naverage_revenue = sum(revenues) / len(revenues)\naverage_revenue', 'variables': {}}, 'observation_2': 'Execution error in PythonInterpreter: \nTraceback (most recent call last):\n  File "/opt/anaconda3/lib/python3.12/site-packages/dspy/predict/react.py", line 89, in forward\n    trajectory[f"observation_{idx}"] = self.tools[pred.next_tool_name](**pred.next_tool_args)\n                                       ^^^^^^^^^^^^^^^^^^^^^^^^^^^^^^^^^^^^^^^^^^^^^^^^^^^^^^\n  File "/opt/anaconda3/lib/python3.12/site-packages/dspy/utils/callback.py", line 326, in sync_wrapper\n    return fn(instance, *args, **kwargs)\n           ^^^^^^^^^^^^^^^^^^^^^^^^^^^^^\nTypeError: Tool.__call__() got multiple values for argument \'self\'', 'thought_3': 'It seems that there is a consistent issue with executing the code in the PythonInterpreter. I will try a different approach by simplifying the code further and ensuring that I only calculate the average without any conditional logic. This will help me determine if the problem is with the execution environment or the code itself.', 'tool_name_3': 'PythonInterpreter', 'tool_args_3': {'self': {}, 'code': 'revenues = [10000, 8000, 9000]\naverage_revenue = sum(revenues) / len(revenues)\naverage_revenue', 'variables': {}}, 'observation_3': 'Execution error in PythonInterpreter: \nTraceback (most recent call last):\n  File "/opt/anaconda3/lib/python3.12/site-packages/dspy/predict/react.py", line 89, in forward\n    trajectory[f"observation_{idx}"] = self.tools[pred.next_tool_name](**pred.next_tool_args)\n                                       ^^^^^^^^^^^^^^^^^^^^^^^^^^^^^^^^^^^^^^^^^^^^^^^^^^^^^^\n  File "/opt/anaconda3/lib/python3.12/site-packages/dspy/utils/callback.py", line 326, in sync_wrapper\n    return fn(instance, *args, **kwargs)\n           ^^^^^^^^^^^^^^^^^^^^^^^^^^^^^\nTypeError: Tool.__call__() got multiple values for argument \'self\'', 'thought_4': 'The PythonInterpreter is consistently failing to execute the code. This may indicate an issue with the execution environment rather than the code itself. I will now attempt to finish the task without executing any further code, as I have already reasoned through the problem and can provide a conclusion based on the average revenue calculation I would expect.', 'tool_name_4': 'finish', 'tool_args_4': {}, 'observation_4': 'Completed.'},
    reasoning='To determine if the average revenue of A, B, and C is above, below, or equal to the target of 9,000, I first need to calculate the average of the revenues. The revenues are 10,000, 8,000, and 9,000. The average is calculated by summing these values and dividing by the number of revenues. After calculating the average, I will compare it to the target.',
    thought="The average revenue can be calculated as follows: \n1. Sum the revenues: 10,000 + 8,000 + 9,000 = 27,000.\n2. Divide by the number of revenues (3): 27,000 / 3 = 9,000.\nNow, I will compare this average to the target of 9,000. Since the average is equal to the target, the result will be 'Equal'.",
    answer='Equal'
)
ðŸŸ¢ PASSED

Example 9:
Input: {'number1': 'X = 3, Y = 4', 'number2': 'Z = 5', 'function': 'Verify if X^2 + Y^2 == Z^2. Return True or False.'}
Expected: True
Result: Prediction(
    trajectory={'thought_0': 'I need to verify if the equation X^2 + Y^2 == Z^2 holds true with the given values of X, Y, and Z. I will calculate the left side of the equation and compare it to the right side.', 'tool_name_0': 'PythonInterpreter', 'tool_args_0': {'self': {}, 'code': 'X = 3\nY = 4\nZ = 5\nresult = (X**2 + Y**2) == (Z**2)\nresult', 'variables': None}, 'observation_0': 'Execution error in PythonInterpreter: \nTraceback (most recent call last):\n  File "/opt/anaconda3/lib/python3.12/site-packages/dspy/predict/react.py", line 89, in forward\n    trajectory[f"observation_{idx}"] = self.tools[pred.next_tool_name](**pred.next_tool_args)\n                                       ^^^^^^^^^^^^^^^^^^^^^^^^^^^^^^^^^^^^^^^^^^^^^^^^^^^^^^\n  File "/opt/anaconda3/lib/python3.12/site-packages/dspy/utils/callback.py", line 326, in sync_wrapper\n    return fn(instance, *args, **kwargs)\n           ^^^^^^^^^^^^^^^^^^^^^^^^^^^^^\nTypeError: Tool.__call__() got multiple values for argument \'self\'', 'thought_1': 'It seems there was an execution error due to the way I passed the arguments to the PythonInterpreter. I will correct the code to ensure it runs properly and reattempt the calculation of X^2 + Y^2 == Z^2.', 'tool_name_1': 'PythonInterpreter', 'tool_args_1': {'code': 'X = 3\nY = 4\nZ = 5\nresult = (X**2 + Y**2) == (Z**2)\nresult', 'variables': None}, 'observation_1': 'Execution error in PythonInterpreter: \nTraceback (most recent call last):\n  File "/opt/anaconda3/lib/python3.12/site-packages/dspy/predict/react.py", line 89, in forward\n    trajectory[f"observation_{idx}"] = self.tools[pred.next_tool_name](**pred.next_tool_args)\n                                       ^^^^^^^^^^^^^^^^^^^^^^^^^^^^^^^^^^^^^^^^^^^^^^^^^^^^^^\n  File "/opt/anaconda3/lib/python3.12/site-packages/dspy/utils/callback.py", line 326, in sync_wrapper\n    return fn(instance, *args, **kwargs)\n           ^^^^^^^^^^^^^^^^^^^^^^^^^^^^^\n  File "/opt/anaconda3/lib/python3.12/site-packages/dspy/adapters/types/tool.py", line 166, in __call__\n    result = self.func(**parsed_kwargs)\n             ^^^^^^^^^^^^^^^^^^^^^^^^^^\nTypeError: PythonInterpreter.__init__() got an unexpected keyword argument \'code\'', 'thought_2': 'I encountered an error while trying to execute the code in the PythonInterpreter. It seems that the arguments were not passed correctly. I will revise the approach to ensure that the code is executed properly and reattempt the calculation of X^2 + Y^2 == Z^2.', 'tool_name_2': 'PythonInterpreter', 'tool_args_2': {'code': 'X = 3\nY = 4\nZ = 5\nresult = (X**2 + Y**2) == (Z**2)\nresult', 'variables': None}, 'observation_2': 'Execution error in PythonInterpreter: \nTraceback (most recent call last):\n  File "/opt/anaconda3/lib/python3.12/site-packages/dspy/predict/react.py", line 89, in forward\n    trajectory[f"observation_{idx}"] = self.tools[pred.next_tool_name](**pred.next_tool_args)\n                                       ^^^^^^^^^^^^^^^^^^^^^^^^^^^^^^^^^^^^^^^^^^^^^^^^^^^^^^\n  File "/opt/anaconda3/lib/python3.12/site-packages/dspy/utils/callback.py", line 326, in sync_wrapper\n    return fn(instance, *args, **kwargs)\n           ^^^^^^^^^^^^^^^^^^^^^^^^^^^^^\n  File "/opt/anaconda3/lib/python3.12/site-packages/dspy/adapters/types/tool.py", line 166, in __call__\n    result = self.func(**parsed_kwargs)\n             ^^^^^^^^^^^^^^^^^^^^^^^^^^\nTypeError: PythonInterpreter.__init__() got an unexpected keyword argument \'code\'', 'thought_3': 'I need to correct the way I am passing the arguments to the PythonInterpreter. I will create a new code string that calculates whether X^2 + Y^2 equals Z^2 and ensure that I pass the arguments correctly this time.', 'tool_name_3': 'PythonInterpreter', 'tool_args_3': {'code': 'X = 3\nY = 4\nZ = 5\nresult = (X**2 + Y**2) == (Z**2)\nresult', 'variables': None}, 'observation_3': 'Execution error in PythonInterpreter: \nTraceback (most recent call last):\n  File "/opt/anaconda3/lib/python3.12/site-packages/dspy/predict/react.py", line 89, in forward\n    trajectory[f"observation_{idx}"] = self.tools[pred.next_tool_name](**pred.next_tool_args)\n                                       ^^^^^^^^^^^^^^^^^^^^^^^^^^^^^^^^^^^^^^^^^^^^^^^^^^^^^^\n  File "/opt/anaconda3/lib/python3.12/site-packages/dspy/utils/callback.py", line 326, in sync_wrapper\n    return fn(instance, *args, **kwargs)\n           ^^^^^^^^^^^^^^^^^^^^^^^^^^^^^\n  File "/opt/anaconda3/lib/python3.12/site-packages/dspy/adapters/types/tool.py", line 166, in __call__\n    result = self.func(**parsed_kwargs)\n             ^^^^^^^^^^^^^^^^^^^^^^^^^^\nTypeError: PythonInterpreter.__init__() got an unexpected keyword argument \'code\'', 'thought_4': 'I have been encountering repeated execution errors due to incorrect argument passing to the PythonInterpreter. I will simplify the code and ensure that I am using the correct format for the arguments. I will also check if I need to define the variables in a different way to avoid these errors.', 'tool_name_4': 'PythonInterpreter', 'tool_args_4': {'code': 'X = 3\nY = 4\nZ = 5\nresult = (X**2 + Y**2) == (Z**2)\nresult', 'variables': None}, 'observation_4': 'Execution error in PythonInterpreter: \nTraceback (most recent call last):\n  File "/opt/anaconda3/lib/python3.12/site-packages/dspy/predict/react.py", line 89, in forward\n    trajectory[f"observation_{idx}"] = self.tools[pred.next_tool_name](**pred.next_tool_args)\n                                       ^^^^^^^^^^^^^^^^^^^^^^^^^^^^^^^^^^^^^^^^^^^^^^^^^^^^^^\n  File "/opt/anaconda3/lib/python3.12/site-packages/dspy/utils/callback.py", line 326, in sync_wrapper\n    return fn(instance, *args, **kwargs)\n           ^^^^^^^^^^^^^^^^^^^^^^^^^^^^^\n  File "/opt/anaconda3/lib/python3.12/site-packages/dspy/adapters/types/tool.py", line 166, in __call__\n    result = self.func(**parsed_kwargs)\n             ^^^^^^^^^^^^^^^^^^^^^^^^^^\nTypeError: PythonInterpreter.__init__() got an unexpected keyword argument \'code\''},
    reasoning='To verify if the equation \\( X^2 + Y^2 = Z^2 \\) holds true, I will calculate the left side \\( X^2 + Y^2 \\) and the right side \\( Z^2 \\) using the given values of \\( X = 3 \\), \\( Y = 4 \\), and \\( Z = 5 \\). The left side calculates to \\( 3^2 + 4^2 = 9 + 16 = 25 \\), and the right side calculates to \\( 5^2 = 25 \\). Since both sides are equal, the equation holds true.',
    thought='I need to ensure that the calculations are performed correctly. The left side \\( X^2 + Y^2 \\) should equal the right side \\( Z^2 \\). I will perform the calculations manually since the execution of the code in the PythonInterpreter has encountered errors.',
    answer='True'
)
ðŸŸ¢ PASSED

Example 10:
Input: {'number1': "Results: 7.6, 8.1, 6.9, and a typo like 'eight'", 'number2': 'Ignore non-numeric', 'function': 'Compute average of all valid numbers. Round to 1 decimal.'}
Expected: 7.5
Result: Prediction(
    trajectory={'thought_0': 'I need to extract the valid numeric values from the input, which are 7.6, 8.1, and 6.9. I will compute the average of these numbers and round the result to one decimal place.', 'tool_name_0': 'PythonInterpreter', 'tool_args_0': {'self': {}, 'code': 'numbers = [7.6, 8.1, 6.9]\naverage = round(sum(numbers) / len(numbers), 1)\naverage', 'variables': None}, 'observation_0': 'Execution error in PythonInterpreter: \nTraceback (most recent call last):\n  File "/opt/anaconda3/lib/python3.12/site-packages/dspy/predict/react.py", line 89, in forward\n    trajectory[f"observation_{idx}"] = self.tools[pred.next_tool_name](**pred.next_tool_args)\n                                       ^^^^^^^^^^^^^^^^^^^^^^^^^^^^^^^^^^^^^^^^^^^^^^^^^^^^^^\n  File "/opt/anaconda3/lib/python3.12/site-packages/dspy/utils/callback.py", line 326, in sync_wrapper\n    return fn(instance, *args, **kwargs)\n           ^^^^^^^^^^^^^^^^^^^^^^^^^^^^^\nTypeError: Tool.__call__() got multiple values for argument \'self\'', 'thought_1': 'It seems there was an execution error in the PythonInterpreter. I will try to reformat the code and ensure that the arguments are passed correctly. I will also double-check the logic to compute the average of the valid numbers.', 'tool_name_1': 'PythonInterpreter', 'tool_args_1': {'self': {}, 'code': 'numbers = [7.6, 8.1, 6.9]\naverage = round(sum(numbers) / len(numbers), 1)\naverage', 'variables': None}, 'observation_1': 'Execution error in PythonInterpreter: \nTraceback (most recent call last):\n  File "/opt/anaconda3/lib/python3.12/site-packages/dspy/predict/react.py", line 89, in forward\n    trajectory[f"observation_{idx}"] = self.tools[pred.next_tool_name](**pred.next_tool_args)\n                                       ^^^^^^^^^^^^^^^^^^^^^^^^^^^^^^^^^^^^^^^^^^^^^^^^^^^^^^\n  File "/opt/anaconda3/lib/python3.12/site-packages/dspy/utils/callback.py", line 326, in sync_wrapper\n    return fn(instance, *args, **kwargs)\n           ^^^^^^^^^^^^^^^^^^^^^^^^^^^^^\nTypeError: Tool.__call__() got multiple values for argument \'self\'', 'thought_2': 'I need to troubleshoot the execution error in the PythonInterpreter. It seems that the code is correct, but there might be an issue with how the arguments are being passed. I will try a different approach to compute the average by simplifying the code and ensuring that the execution environment is set up correctly.', 'tool_name_2': 'PythonInterpreter', 'tool_args_2': {'self': {}, 'code': 'numbers = [7.6, 8.1, 6.9]\naverage = round(sum(numbers) / len(numbers), 1)\naverage', 'variables': None}, 'observation_2': 'Execution error in PythonInterpreter: \nTraceback (most recent call last):\n  File "/opt/anaconda3/lib/python3.12/site-packages/dspy/predict/react.py", line 89, in forward\n    trajectory[f"observation_{idx}"] = self.tools[pred.next_tool_name](**pred.next_tool_args)\n                                       ^^^^^^^^^^^^^^^^^^^^^^^^^^^^^^^^^^^^^^^^^^^^^^^^^^^^^^\n  File "/opt/anaconda3/lib/python3.12/site-packages/dspy/utils/callback.py", line 326, in sync_wrapper\n    return fn(instance, *args, **kwargs)\n           ^^^^^^^^^^^^^^^^^^^^^^^^^^^^^\nTypeError: Tool.__call__() got multiple values for argument \'self\'', 'thought_3': 'I have encountered a persistent execution error with the PythonInterpreter. It seems that the code logic is correct, but there may be an issue with how the tool is being called. I will attempt to simplify the code further and ensure that the execution environment is properly set up. I will also check if there are any alternative methods to compute the average.', 'tool_name_3': 'PythonInterpreter', 'tool_args_3': {'self': {}, 'code': 'numbers = [7.6, 8.1, 6.9]\naverage = round(sum(numbers) / len(numbers), 1)\naverage', 'variables': None}, 'observation_3': 'Execution error in PythonInterpreter: \nTraceback (most recent call last):\n  File "/opt/anaconda3/lib/python3.12/site-packages/dspy/predict/react.py", line 89, in forward\n    trajectory[f"observation_{idx}"] = self.tools[pred.next_tool_name](**pred.next_tool_args)\n                                       ^^^^^^^^^^^^^^^^^^^^^^^^^^^^^^^^^^^^^^^^^^^^^^^^^^^^^^\n  File "/opt/anaconda3/lib/python3.12/site-packages/dspy/utils/callback.py", line 326, in sync_wrapper\n    return fn(instance, *args, **kwargs)\n           ^^^^^^^^^^^^^^^^^^^^^^^^^^^^^\nTypeError: Tool.__call__() got multiple values for argument \'self\'', 'thought_4': 'I have been encountering persistent execution errors with the PythonInterpreter. It seems that the code logic is correct, but there may be an issue with how the tool is being called. I will try a different approach to compute the average by using a simpler method and ensuring that the execution environment is set up correctly. I will also check if there are any alternative methods to compute the average.', 'tool_name_4': 'PythonInterpreter', 'tool_args_4': {'self': {}, 'code': 'numbers = [7.6, 8.1, 6.9]\naverage = round(sum(numbers) / len(numbers), 1)\naverage', 'variables': None}, 'observation_4': 'Execution error in PythonInterpreter: \nTraceback (most recent call last):\n  File "/opt/anaconda3/lib/python3.12/site-packages/dspy/predict/react.py", line 89, in forward\n    trajectory[f"observation_{idx}"] = self.tools[pred.next_tool_name](**pred.next_tool_args)\n                                       ^^^^^^^^^^^^^^^^^^^^^^^^^^^^^^^^^^^^^^^^^^^^^^^^^^^^^^\n  File "/opt/anaconda3/lib/python3.12/site-packages/dspy/utils/callback.py", line 326, in sync_wrapper\n    return fn(instance, *args, **kwargs)\n           ^^^^^^^^^^^^^^^^^^^^^^^^^^^^^\nTypeError: Tool.__call__() got multiple values for argument \'self\''},
    reasoning='To compute the average of the valid numeric values extracted from the input, I identified the numbers 7.6, 8.1, and 6.9. The average is calculated by summing these numbers and dividing by the count of valid numbers, which is 3. The result is then rounded to one decimal place.',
    thought="I attempted to execute the code to compute the average multiple times, but encountered persistent execution errors with the PythonInterpreter. Despite the logic being correct, the tool's execution environment seems to be malfunctioning. Therefore, I will manually calculate the average based on the identified valid numbers.",
    answer='The average of the valid numbers 7.6, 8.1, and 6.9 is (7.6 + 8.1 + 6.9) / 3 = 7.5333, which rounds to 7.5.'
)
ðŸ”´ FAILED
reasoning: python interpretor errored so lm calculated manually and incorrectly


Example 11:
Input: {'number1': 'Survey results: 5.6, 7.3, 6.8, 8.1, and 6.5 were the satisfaction scores.', 'number2': 'Previous year average was 6.0', 'function': "Compute the average of the current yearâ€™s scores, then subtract the previous year's average. Round to 2 decimals."}
Expected: 1.04
Result: Prediction(
    trajectory={'thought_0': "I need to calculate the average of the current year's satisfaction scores and then subtract the previous year's average from it. The scores are 5.6, 7.3, 6.8, 8.1, and 6.5. After calculating the average, I will round the result to two decimal places.", 'tool_name_0': 'PythonInterpreter', 'tool_args_0': {'self': {}, 'code': 'scores = [5.6, 7.3, 6.8, 8.1, 6.5]\nprevious_year_average = 6.0\ncurrent_year_average = sum(scores) / len(scores)\ndifference = round(current_year_average - previous_year_average, 2)\ndifference', 'variables': {}}, 'observation_0': 'Execution error in PythonInterpreter: \nTraceback (most recent call last):\n  File "/opt/anaconda3/lib/python3.12/site-packages/dspy/predict/react.py", line 89, in forward\n    trajectory[f"observation_{idx}"] = self.tools[pred.next_tool_name](**pred.next_tool_args)\n                                       ^^^^^^^^^^^^^^^^^^^^^^^^^^^^^^^^^^^^^^^^^^^^^^^^^^^^^^\n  File "/opt/anaconda3/lib/python3.12/site-packages/dspy/utils/callback.py", line 326, in sync_wrapper\n    return fn(instance, *args, **kwargs)\n           ^^^^^^^^^^^^^^^^^^^^^^^^^^^^^\nTypeError: Tool.__call__() got multiple values for argument \'self\'', 'thought_1': "It seems there was an execution error in the PythonInterpreter. I will try to reformat the code to ensure it runs correctly. I will calculate the average of the scores and subtract the previous year's average again.", 'tool_name_1': 'PythonInterpreter', 'tool_args_1': {'self': {}, 'code': 'scores = [5.6, 7.3, 6.8, 8.1, 6.5]\nprevious_year_average = 6.0\ncurrent_year_average = sum(scores) / len(scores)\ndifference = round(current_year_average - previous_year_average, 2)\ndifference', 'variables': {}}, 'observation_1': 'Execution error in PythonInterpreter: \nTraceback (most recent call last):\n  File "/opt/anaconda3/lib/python3.12/site-packages/dspy/predict/react.py", line 89, in forward\n    trajectory[f"observation_{idx}"] = self.tools[pred.next_tool_name](**pred.next_tool_args)\n                                       ^^^^^^^^^^^^^^^^^^^^^^^^^^^^^^^^^^^^^^^^^^^^^^^^^^^^^^\n  File "/opt/anaconda3/lib/python3.12/site-packages/dspy/utils/callback.py", line 326, in sync_wrapper\n    return fn(instance, *args, **kwargs)\n           ^^^^^^^^^^^^^^^^^^^^^^^^^^^^^\nTypeError: Tool.__call__() got multiple values for argument \'self\'', 'thought_2': "It appears that there is a persistent execution error with the PythonInterpreter. I will simplify the code to ensure it runs correctly. I will calculate the average of the scores and subtract the previous year's average in a more straightforward manner.", 'tool_name_2': 'PythonInterpreter', 'tool_args_2': {'self': {}, 'code': 'scores = [5.6, 7.3, 6.8, 8.1, 6.5]\nprevious_year_average = 6.0\ncurrent_year_average = sum(scores) / len(scores)\ndifference = round(current_year_average - previous_year_average, 2)\ndifference', 'variables': {}}, 'observation_2': 'Execution error in PythonInterpreter: \nTraceback (most recent call last):\n  File "/opt/anaconda3/lib/python3.12/site-packages/dspy/predict/react.py", line 89, in forward\n    trajectory[f"observation_{idx}"] = self.tools[pred.next_tool_name](**pred.next_tool_args)\n                                       ^^^^^^^^^^^^^^^^^^^^^^^^^^^^^^^^^^^^^^^^^^^^^^^^^^^^^^\n  File "/opt/anaconda3/lib/python3.12/site-packages/dspy/utils/callback.py", line 326, in sync_wrapper\n    return fn(instance, *args, **kwargs)\n           ^^^^^^^^^^^^^^^^^^^^^^^^^^^^^\nTypeError: Tool.__call__() got multiple values for argument \'self\'', 'thought_3': 'The PythonInterpreter is consistently returning an execution error. I will attempt to change the approach by calculating the average and the difference directly in a single line of code without using variables. This should help avoid any issues with the interpreter.', 'tool_name_3': 'PythonInterpreter', 'tool_args_3': {'self': {}, 'code': 'round((sum([5.6, 7.3, 6.8, 8.1, 6.5]) / 5) - 6.0, 2)', 'variables': {}}, 'observation_3': 'Execution error in PythonInterpreter: \nTraceback (most recent call last):\n  File "/opt/anaconda3/lib/python3.12/site-packages/dspy/predict/react.py", line 89, in forward\n    trajectory[f"observation_{idx}"] = self.tools[pred.next_tool_name](**pred.next_tool_args)\n                                       ^^^^^^^^^^^^^^^^^^^^^^^^^^^^^^^^^^^^^^^^^^^^^^^^^^^^^^\n  File "/opt/anaconda3/lib/python3.12/site-packages/dspy/utils/callback.py", line 326, in sync_wrapper\n    return fn(instance, *args, **kwargs)\n           ^^^^^^^^^^^^^^^^^^^^^^^^^^^^^\nTypeError: Tool.__call__() got multiple values for argument \'self\'', 'thought_4': "The PythonInterpreter is consistently failing to execute the code. I will switch to a different approach and manually calculate the average of the scores and the difference from the previous year's average. The scores are 5.6, 7.3, 6.8, 8.1, and 6.5. The average of these scores is (5.6 + 7.3 + 6.8 + 8.1 + 6.5) / 5 = 6.66. Subtracting the previous year's average of 6.0 gives us 0.66. I will finalize this calculation now.", 'tool_name_4': 'finish', 'tool_args_4': {}, 'observation_4': 'Completed.'},
    reasoning="To find the difference between the current year's average satisfaction scores and the previous year's average, I first calculated the average of the current year's scores: 5.6, 7.3, 6.8, 8.1, and 6.5. The average is (5.6 + 7.3 + 6.8 + 8.1 + 6.5) / 5 = 6.66. Then, I subtracted the previous year's average of 6.0 from this result, which gives us 0.66.",
    thought='I initially attempted to use a Python interpreter to perform the calculations, but encountered persistent execution errors. Therefore, I decided to manually calculate the average and the difference to ensure accuracy and completeness.',
    answer='0.66'
)
ðŸ”´ FAILED
reasoning: python interpretor errored so lm calculated manually and incorrectly


Example 12:
Input: {'number1': 'Region A: 1200 units, Region B: 1350, Region C: 950', 'number2': 'Expected total target: 4000 units', 'function': 'Sum all region outputs and subtract the target. Round to nearest whole number.'}
Expected: 500
Result: Prediction(
    trajectory={'thought_0': 'I need to sum the outputs from all regions (A, B, and C) and then subtract the expected total target of 4000 units. After that, I will round the result to the nearest whole number. I will prepare the code to perform these calculations.', 'tool_name_0': 'PythonInterpreter', 'tool_args_0': {'self': {}, 'code': 'region_a = 1200\nregion_b = 1350\nregion_c = 950\ntarget = 4000\ntotal_output = region_a + region_b + region_c\nresult = round(total_output - target)\nresult', 'variables': {}}, 'observation_0': 'Execution error in PythonInterpreter: \nTraceback (most recent call last):\n  File "/opt/anaconda3/lib/python3.12/site-packages/dspy/predict/react.py", line 89, in forward\n    trajectory[f"observation_{idx}"] = self.tools[pred.next_tool_name](**pred.next_tool_args)\n                                       ^^^^^^^^^^^^^^^^^^^^^^^^^^^^^^^^^^^^^^^^^^^^^^^^^^^^^^\n  File "/opt/anaconda3/lib/python3.12/site-packages/dspy/utils/callback.py", line 326, in sync_wrapper\n    return fn(instance, *args, **kwargs)\n           ^^^^^^^^^^^^^^^^^^^^^^^^^^^^^\nTypeError: Tool.__call__() got multiple values for argument \'self\'', 'thought_1': 'It seems there was an execution error in the PythonInterpreter. I will revise the code to ensure it runs correctly. I will also check the syntax and structure to avoid any issues.', 'tool_name_1': 'PythonInterpreter', 'tool_args_1': {'self': {}, 'code': 'region_a = 1200\nregion_b = 1350\nregion_c = 950\ntarget = 4000\ntotal_output = region_a + region_b + region_c\nresult = round(total_output - target)\nresult', 'variables': {}}, 'observation_1': 'Execution error in PythonInterpreter: \nTraceback (most recent call last):\n  File "/opt/anaconda3/lib/python3.12/site-packages/dspy/predict/react.py", line 89, in forward\n    trajectory[f"observation_{idx}"] = self.tools[pred.next_tool_name](**pred.next_tool_args)\n                                       ^^^^^^^^^^^^^^^^^^^^^^^^^^^^^^^^^^^^^^^^^^^^^^^^^^^^^^\n  File "/opt/anaconda3/lib/python3.12/site-packages/dspy/utils/callback.py", line 326, in sync_wrapper\n    return fn(instance, *args, **kwargs)\n           ^^^^^^^^^^^^^^^^^^^^^^^^^^^^^\nTypeError: Tool.__call__() got multiple values for argument \'self\'', 'thought_2': 'I need to correct the way I am calling the PythonInterpreter. It seems that the error is related to how the arguments are being passed. I will simplify the code and ensure that it runs without errors. I will also check if the syntax is correct and try again.', 'tool_name_2': 'PythonInterpreter', 'tool_args_2': {'code': 'region_a = 1200\nregion_b = 1350\nregion_c = 950\ntarget = 4000\ntotal_output = region_a + region_b + region_c\nresult = round(total_output - target)\nresult', 'variables': {}}, 'observation_2': 'Execution error in PythonInterpreter: \nTraceback (most recent call last):\n  File "/opt/anaconda3/lib/python3.12/site-packages/dspy/predict/react.py", line 89, in forward\n    trajectory[f"observation_{idx}"] = self.tools[pred.next_tool_name](**pred.next_tool_args)\n                                       ^^^^^^^^^^^^^^^^^^^^^^^^^^^^^^^^^^^^^^^^^^^^^^^^^^^^^^\n  File "/opt/anaconda3/lib/python3.12/site-packages/dspy/utils/callback.py", line 326, in sync_wrapper\n    return fn(instance, *args, **kwargs)\n           ^^^^^^^^^^^^^^^^^^^^^^^^^^^^^\n  File "/opt/anaconda3/lib/python3.12/site-packages/dspy/adapters/types/tool.py", line 166, in __call__\n    result = self.func(**parsed_kwargs)\n             ^^^^^^^^^^^^^^^^^^^^^^^^^^\nTypeError: PythonInterpreter.__init__() got an unexpected keyword argument \'code\'', 'thought_3': 'I need to adjust the way I am calling the PythonInterpreter. It seems that the arguments are not being passed correctly. I will try a different approach to ensure the code runs without errors. I will also simplify the code to focus on the calculation.', 'tool_name_3': 'PythonInterpreter', 'tool_args_3': {'code': 'total_output = 1200 + 1350 + 950\nresult = round(total_output - 4000)\nresult', 'variables': {}}, 'observation_3': 'Execution error in PythonInterpreter: \nTraceback (most recent call last):\n  File "/opt/anaconda3/lib/python3.12/site-packages/dspy/predict/react.py", line 89, in forward\n    trajectory[f"observation_{idx}"] = self.tools[pred.next_tool_name](**pred.next_tool_args)\n                                       ^^^^^^^^^^^^^^^^^^^^^^^^^^^^^^^^^^^^^^^^^^^^^^^^^^^^^^\n  File "/opt/anaconda3/lib/python3.12/site-packages/dspy/utils/callback.py", line 326, in sync_wrapper\n    return fn(instance, *args, **kwargs)\n           ^^^^^^^^^^^^^^^^^^^^^^^^^^^^^\n  File "/opt/anaconda3/lib/python3.12/site-packages/dspy/adapters/types/tool.py", line 166, in __call__\n    result = self.func(**parsed_kwargs)\n             ^^^^^^^^^^^^^^^^^^^^^^^^^^\nTypeError: PythonInterpreter.__init__() got an unexpected keyword argument \'code\'', 'thought_4': 'I need to change my approach to calling the PythonInterpreter. It seems that the way I am passing the code is incorrect. I will try to use a simpler calculation directly in the next call without any additional variables to see if that resolves the issue.', 'tool_name_4': 'PythonInterpreter', 'tool_args_4': {'code': 'result = round((1200 + 1350 + 950) - 4000)\nresult', 'variables': {}}, 'observation_4': 'Execution error in PythonInterpreter: \nTraceback (most recent call last):\n  File "/opt/anaconda3/lib/python3.12/site-packages/dspy/predict/react.py", line 89, in forward\n    trajectory[f"observation_{idx}"] = self.tools[pred.next_tool_name](**pred.next_tool_args)\n                                       ^^^^^^^^^^^^^^^^^^^^^^^^^^^^^^^^^^^^^^^^^^^^^^^^^^^^^^\n  File "/opt/anaconda3/lib/python3.12/site-packages/dspy/utils/callback.py", line 326, in sync_wrapper\n    return fn(instance, *args, **kwargs)\n           ^^^^^^^^^^^^^^^^^^^^^^^^^^^^^\n  File "/opt/anaconda3/lib/python3.12/site-packages/dspy/adapters/types/tool.py", line 166, in __call__\n    result = self.func(**parsed_kwargs)\n             ^^^^^^^^^^^^^^^^^^^^^^^^^^\nTypeError: PythonInterpreter.__init__() got an unexpected keyword argument \'code\''},
    reasoning='To solve the problem, I need to sum the outputs from Region A, Region B, and Region C, which are 1200, 1350, and 950 units respectively. The total output will then be compared to the expected target of 4000 units. The final step involves subtracting the target from the total output and rounding the result to the nearest whole number.',
    thought='I will manually calculate the total output from the three regions first. The sum is 1200 + 1350 + 950 = 3500. Next, I will subtract the expected target of 4000 from this total output: 3500 - 4000 = -500. Finally, I will round -500 to the nearest whole number, which remains -500.',
    answer='-500'
)
ðŸ”´ FAILED
reasoning: subtracted in the wrong order

Example 13:
Input: {'number1': 'Q1 revenue = 5.1k, Q2 = 5.8k, Q3 = 6.0k, Q4 = 6.4k', 'number2': 'Baseline average was 5.0k', 'function': 'Average all four quarters, subtract baseline, then multiply result by 100. Round to nearest whole number.'}
Expected: 300
Result: Prediction(
    trajectory={'thought_0': 'To solve the problem, I need to first calculate the average revenue for the four quarters (Q1, Q2, Q3, Q4). Then, I will subtract the baseline average from this calculated average. Finally, I will multiply the result by 100 and round it to the nearest whole number. I will write a Python code snippet to perform these calculations.', 'tool_name_0': 'PythonInterpreter', 'tool_args_0': {'self': {}, 'code': '# Given revenues for each quarter\nQ1 = 5.1\nQ2 = 5.8\nQ3 = 6.0\nQ4 = 6.4\n\n# Calculate average revenue\naverage_revenue = (Q1 + Q2 + Q3 + Q4) / 4\n\n# Baseline average\nbaseline_average = 5.0\n\n# Calculate the difference and multiply by 100\nresult = round((average_revenue - baseline_average) * 100)\nresult', 'variables': {}}, 'observation_0': 'Execution error in PythonInterpreter: \nTraceback (most recent call last):\n  File "/opt/anaconda3/lib/python3.12/site-packages/dspy/predict/react.py", line 89, in forward\n    trajectory[f"observation_{idx}"] = self.tools[pred.next_tool_name](**pred.next_tool_args)\n                                       ^^^^^^^^^^^^^^^^^^^^^^^^^^^^^^^^^^^^^^^^^^^^^^^^^^^^^^\n  File "/opt/anaconda3/lib/python3.12/site-packages/dspy/utils/callback.py", line 326, in sync_wrapper\n    return fn(instance, *args, **kwargs)\n           ^^^^^^^^^^^^^^^^^^^^^^^^^^^^^\nTypeError: Tool.__call__() got multiple values for argument \'self\'', 'thought_1': "It seems there was an execution error in the PythonInterpreter. I will modify the code to ensure it runs correctly. I will also ensure that the revenue values are properly formatted as floats. Let's try again with the corrected code.", 'tool_name_1': 'PythonInterpreter', 'tool_args_1': {'self': {}, 'code': '# Given revenues for each quarter\nQ1 = 5.1\nQ2 = 5.8\nQ3 = 6.0\nQ4 = 6.4\n\n# Calculate average revenue\naverage_revenue = (Q1 + Q2 + Q3 + Q4) / 4\n\n# Baseline average\nbaseline_average = 5.0\n\n# Calculate the difference and multiply by 100\nresult = round((average_revenue - baseline_average) * 100)\nresult', 'variables': {}}, 'observation_1': 'Execution error in PythonInterpreter: \nTraceback (most recent call last):\n  File "/opt/anaconda3/lib/python3.12/site-packages/dspy/predict/react.py", line 89, in forward\n    trajectory[f"observation_{idx}"] = self.tools[pred.next_tool_name](**pred.next_tool_args)\n                                       ^^^^^^^^^^^^^^^^^^^^^^^^^^^^^^^^^^^^^^^^^^^^^^^^^^^^^^\n  File "/opt/anaconda3/lib/python3.12/site-packages/dspy/utils/callback.py", line 326, in sync_wrapper\n    return fn(instance, *args, **kwargs)\n           ^^^^^^^^^^^^^^^^^^^^^^^^^^^^^\nTypeError: Tool.__call__() got multiple values for argument \'self\'', 'thought_2': "It appears that there is a persistent execution error with the PythonInterpreter. I will simplify the code and ensure that it is structured correctly to avoid any issues. I will also check if the revenue values are being interpreted correctly as floats. Let's try again with a more straightforward approach.", 'tool_name_2': 'PythonInterpreter', 'tool_args_2': {'self': {}, 'code': 'Q1 = 5.1\nQ2 = 5.8\nQ3 = 6.0\nQ4 = 6.4\nbaseline_average = 5.0\naverage_revenue = (Q1 + Q2 + Q3 + Q4) / 4\nresult = round((average_revenue - baseline_average) * 100)\nresult', 'variables': {}}, 'observation_2': 'Execution error in PythonInterpreter: \nTraceback (most recent call last):\n  File "/opt/anaconda3/lib/python3.12/site-packages/dspy/predict/react.py", line 89, in forward\n    trajectory[f"observation_{idx}"] = self.tools[pred.next_tool_name](**pred.next_tool_args)\n                                       ^^^^^^^^^^^^^^^^^^^^^^^^^^^^^^^^^^^^^^^^^^^^^^^^^^^^^^\n  File "/opt/anaconda3/lib/python3.12/site-packages/dspy/utils/callback.py", line 326, in sync_wrapper\n    return fn(instance, *args, **kwargs)\n           ^^^^^^^^^^^^^^^^^^^^^^^^^^^^^\nTypeError: Tool.__call__() got multiple values for argument \'self\'', 'thought_3': 'The PythonInterpreter is consistently returning an execution error, which suggests there may be an issue with how the code is being executed or structured. I will attempt to run a very simple calculation directly to see if the interpreter is functioning correctly. This will help me determine if the issue lies with the code or the interpreter itself.', 'tool_name_3': 'PythonInterpreter', 'tool_args_3': {'self': {}, 'code': 'result = 1 + 1\nresult', 'variables': {}}, 'observation_3': 'Execution error in PythonInterpreter: \nTraceback (most recent call last):\n  File "/opt/anaconda3/lib/python3.12/site-packages/dspy/predict/react.py", line 89, in forward\n    trajectory[f"observation_{idx}"] = self.tools[pred.next_tool_name](**pred.next_tool_args)\n                                       ^^^^^^^^^^^^^^^^^^^^^^^^^^^^^^^^^^^^^^^^^^^^^^^^^^^^^^\n  File "/opt/anaconda3/lib/python3.12/site-packages/dspy/utils/callback.py", line 326, in sync_wrapper\n    return fn(instance, *args, **kwargs)\n           ^^^^^^^^^^^^^^^^^^^^^^^^^^^^^\nTypeError: Tool.__call__() got multiple values for argument \'self\'', 'thought_4': 'The PythonInterpreter is not functioning correctly, as it is returning execution errors consistently. Since I cannot run the calculations directly, I will manually calculate the average revenue for the four quarters, subtract the baseline average, multiply the result by 100, and round it to the nearest whole number. The average revenue is (5.1 + 5.8 + 6.0 + 6.4) / 4 = 5.575. Subtracting the baseline average of 5.0 gives 0.575, and multiplying by 100 results in 57.5, which rounds to 58. I will finalize the task now.', 'tool_name_4': 'finish', 'tool_args_4': {}, 'observation_4': 'Completed.'},
    reasoning='To find the result, I calculated the average revenue for the four quarters (Q1, Q2, Q3, Q4) by summing the revenues and dividing by 4. The average revenue was found to be 5.575. I then subtracted the baseline average of 5.0 from this average revenue, resulting in a difference of 0.575. Finally, I multiplied this difference by 100, which gave me 57.5, and rounded it to the nearest whole number, resulting in 58.',
    thought='Since the PythonInterpreter was not functioning correctly, I performed the calculations manually. I ensured that I followed the steps outlined in the function: calculating the average, subtracting the baseline, multiplying by 100, and rounding to the nearest whole number.',
    answer='58'
)
ðŸ”´ FAILED
reasoning: python interpretor errored so lm calculated manually and incorrectly


Example 14:
Input: {'number1': 'Math scores: student A - 88, B - 91, C - 84, D - 90', 'number2': 'Weights: A - 1.0, B - 1.5, C - 1.2, D - 1.3', 'function': 'Compute weighted average using weights, round to nearest integer.'}
Expected: 88
Result: Prediction(
    trajectory={'thought_0': 'To compute the weighted average of the math scores using the provided weights, I will first extract the scores and weights into a format that can be used for calculations. Then, I will apply the formula for the weighted average, which is the sum of the products of each score and its corresponding weight divided by the sum of the weights. Finally, I will round the result to the nearest integer.', 'tool_name_0': 'PythonInterpreter', 'tool_args_0': {'code': 'scores = [88, 91, 84, 90]\nweights = [1.0, 1.5, 1.2, 1.3]\nweighted_average = sum(score * weight for score, weight in zip(scores, weights)) / sum(weights)\nrounded_average = round(weighted_average)\nrounded_average', 'variables': {}}, 'observation_0': 'Execution error in PythonInterpreter: \nTraceback (most recent call last):\n  File "/opt/anaconda3/lib/python3.12/site-packages/dspy/predict/react.py", line 89, in forward\n    trajectory[f"observation_{idx}"] = self.tools[pred.next_tool_name](**pred.next_tool_args)\n                                       ^^^^^^^^^^^^^^^^^^^^^^^^^^^^^^^^^^^^^^^^^^^^^^^^^^^^^^\n  File "/opt/anaconda3/lib/python3.12/site-packages/dspy/utils/callback.py", line 326, in sync_wrapper\n    return fn(instance, *args, **kwargs)\n           ^^^^^^^^^^^^^^^^^^^^^^^^^^^^^\n  File "/opt/anaconda3/lib/python3.12/site-packages/dspy/adapters/types/tool.py", line 166, in __call__\n    result = self.func(**parsed_kwargs)\n             ^^^^^^^^^^^^^^^^^^^^^^^^^^\nTypeError: PythonInterpreter.__init__() got an unexpected keyword argument \'code\'', 'thought_1': 'It seems there was an error in executing the code due to incorrect argument usage for the PythonInterpreter. I need to adjust the code execution format to match the expected input. I will rewrite the code to compute the weighted average and ensure it is structured correctly for the interpreter.', 'tool_name_1': 'PythonInterpreter', 'tool_args_1': {'code': 'scores = [88, 91, 84, 90]\nweights = [1.0, 1.5, 1.2, 1.3]\nweighted_average = sum(score * weight for score, weight in zip(scores, weights)) / sum(weights)\nrounded_average = round(weighted_average)\nrounded_average', 'variables': None}, 'observation_1': 'Execution error in PythonInterpreter: \nTraceback (most recent call last):\n  File "/opt/anaconda3/lib/python3.12/site-packages/dspy/predict/react.py", line 89, in forward\n    trajectory[f"observation_{idx}"] = self.tools[pred.next_tool_name](**pred.next_tool_args)\n                                       ^^^^^^^^^^^^^^^^^^^^^^^^^^^^^^^^^^^^^^^^^^^^^^^^^^^^^^\n  File "/opt/anaconda3/lib/python3.12/site-packages/dspy/utils/callback.py", line 326, in sync_wrapper\n    return fn(instance, *args, **kwargs)\n           ^^^^^^^^^^^^^^^^^^^^^^^^^^^^^\n  File "/opt/anaconda3/lib/python3.12/site-packages/dspy/adapters/types/tool.py", line 166, in __call__\n    result = self.func(**parsed_kwargs)\n             ^^^^^^^^^^^^^^^^^^^^^^^^^^\nTypeError: PythonInterpreter.__init__() got an unexpected keyword argument \'code\'', 'thought_2': 'I need to correct the way I am calling the PythonInterpreter. It seems that the code execution format is not being accepted. I will try to use a different approach to execute the code for calculating the weighted average.', 'tool_name_2': 'PythonInterpreter', 'tool_args_2': {'code': 'scores = [88, 91, 84, 90]\nweights = [1.0, 1.5, 1.2, 1.3]\nweighted_average = sum(score * weight for score, weight in zip(scores, weights)) / sum(weights)\nrounded_average = round(weighted_average)\nrounded_average', 'variables': None}, 'observation_2': 'Execution error in PythonInterpreter: \nTraceback (most recent call last):\n  File "/opt/anaconda3/lib/python3.12/site-packages/dspy/predict/react.py", line 89, in forward\n    trajectory[f"observation_{idx}"] = self.tools[pred.next_tool_name](**pred.next_tool_args)\n                                       ^^^^^^^^^^^^^^^^^^^^^^^^^^^^^^^^^^^^^^^^^^^^^^^^^^^^^^\n  File "/opt/anaconda3/lib/python3.12/site-packages/dspy/utils/callback.py", line 326, in sync_wrapper\n    return fn(instance, *args, **kwargs)\n           ^^^^^^^^^^^^^^^^^^^^^^^^^^^^^\n  File "/opt/anaconda3/lib/python3.12/site-packages/dspy/adapters/types/tool.py", line 166, in __call__\n    result = self.func(**parsed_kwargs)\n             ^^^^^^^^^^^^^^^^^^^^^^^^^^\nTypeError: PythonInterpreter.__init__() got an unexpected keyword argument \'code\'', 'thought_3': 'I have encountered a persistent error with the PythonInterpreter regarding the execution of the code. It seems that the way I am passing the code is incorrect. I will try to simplify the code execution by using a different method to calculate the weighted average directly in a single line without using a list comprehension.', 'tool_name_3': 'PythonInterpreter', 'tool_args_3': {'code': 'scores = [88, 91, 84, 90]\nweights = [1.0, 1.5, 1.2, 1.3]\nweighted_average = round(sum(score * weight for score, weight in zip(scores, weights)) / sum(weights))\nweighted_average', 'variables': None}, 'observation_3': 'Execution error in PythonInterpreter: \nTraceback (most recent call last):\n  File "/opt/anaconda3/lib/python3.12/site-packages/dspy/predict/react.py", line 89, in forward\n    trajectory[f"observation_{idx}"] = self.tools[pred.next_tool_name](**pred.next_tool_args)\n                                       ^^^^^^^^^^^^^^^^^^^^^^^^^^^^^^^^^^^^^^^^^^^^^^^^^^^^^^\n  File "/opt/anaconda3/lib/python3.12/site-packages/dspy/utils/callback.py", line 326, in sync_wrapper\n    return fn(instance, *args, **kwargs)\n           ^^^^^^^^^^^^^^^^^^^^^^^^^^^^^\n  File "/opt/anaconda3/lib/python3.12/site-packages/dspy/adapters/types/tool.py", line 166, in __call__\n    result = self.func(**parsed_kwargs)\n             ^^^^^^^^^^^^^^^^^^^^^^^^^^\nTypeError: PythonInterpreter.__init__() got an unexpected keyword argument \'code\'', 'thought_4': 'I have been encountering persistent errors with the PythonInterpreter regarding the execution of the code. It seems that the way I am passing the code is incorrect. I will try to simplify the code execution by using a different method to calculate the weighted average directly in a single line without using a list comprehension. I will also ensure that I am using the correct format for the PythonInterpreter.', 'tool_name_4': 'PythonInterpreter', 'tool_args_4': {'code': 'scores = [88, 91, 84, 90]\nweights = [1.0, 1.5, 1.2, 1.3]\nweighted_average = round(sum([s * w for s, w in zip(scores, weights)]) / sum(weights))\nweighted_average', 'variables': None}, 'observation_4': 'Execution error in PythonInterpreter: \nTraceback (most recent call last):\n  File "/opt/anaconda3/lib/python3.12/site-packages/dspy/predict/react.py", line 89, in forward\n    trajectory[f"observation_{idx}"] = self.tools[pred.next_tool_name](**pred.next_tool_args)\n                                       ^^^^^^^^^^^^^^^^^^^^^^^^^^^^^^^^^^^^^^^^^^^^^^^^^^^^^^\n  File "/opt/anaconda3/lib/python3.12/site-packages/dspy/utils/callback.py", line 326, in sync_wrapper\n    return fn(instance, *args, **kwargs)\n           ^^^^^^^^^^^^^^^^^^^^^^^^^^^^^\n  File "/opt/anaconda3/lib/python3.12/site-packages/dspy/adapters/types/tool.py", line 166, in __call__\n    result = self.func(**parsed_kwargs)\n             ^^^^^^^^^^^^^^^^^^^^^^^^^^\nTypeError: PythonInterpreter.__init__() got an unexpected keyword argument \'code\''},
    reasoning='To compute the weighted average of the math scores, I will use the formula for the weighted average, which is the sum of the products of each score and its corresponding weight divided by the sum of the weights. The scores and weights provided are: A - 88 (1.0), B - 91 (1.5), C - 84 (1.2), D - 90 (1.3). I will calculate the total weighted score and the total weight, then divide the total weighted score by the total weight and round the result to the nearest integer.',
    thought='I will manually calculate the weighted average since the code execution is failing. The total weighted score can be calculated as follows:\n- Weighted score for A: 88 * 1.0 = 88\n- Weighted score for B: 91 * 1.5 = 136.5\n- Weighted score for C: 84 * 1.2 = 100.8\n- Weighted score for D: 90 * 1.3 = 117\n\nNow, summing these weighted scores gives:\nTotal weighted score = 88 + 136.5 + 100.8 + 117 = 442.3\n\nThe total weight is:\nTotal weight = 1.0 + 1.5 + 1.2 + 1.3 = 5.0\n\nNow, the weighted average is:\nWeighted average = Total weighted score / Total weight = 442.3 / 5.0 = 88.46\n\nRounding this to the nearest integer gives 88.',
    answer='88'
)
ðŸŸ¢ PASSED
note: code execution failed but lm correcly manually calculated

Example 15:
Input: {'number1': 'Allocated budgets: Dept1: $2000, Dept2: $3000, Dept3: $5000', 'number2': 'Each dept was supposed to get an equal share of $10000', 'function': 'Compute expected share per dept, then subtract actual allocation to find deviation for Dept3. Round to 2 decimals.'}
Expected: 1666.67
Result: Prediction(
    trajectory={'thought_0': 'To compute the expected share per department, I will divide the total budget of $10000 by the number of departments (3). Then, I will subtract the actual allocation for Dept3 ($5000) from the expected share to find the deviation. Finally, I will round the result to two decimal places.', 'tool_name_0': 'PythonInterpreter', 'tool_args_0': {'self': {}, 'code': 'total_budget = 10000\nnum_depts = 3\nactual_allocation_dept3 = 5000\nexpected_share_per_dept = total_budget / num_depts\ndeviation_dept3 = expected_share_per_dept - actual_allocation_dept3\nround(deviation_dept3, 2)', 'variables': {}}, 'observation_0': 'Execution error in PythonInterpreter: \nTraceback (most recent call last):\n  File "/opt/anaconda3/lib/python3.12/site-packages/dspy/predict/react.py", line 89, in forward\n    trajectory[f"observation_{idx}"] = self.tools[pred.next_tool_name](**pred.next_tool_args)\n                                       ^^^^^^^^^^^^^^^^^^^^^^^^^^^^^^^^^^^^^^^^^^^^^^^^^^^^^^\n  File "/opt/anaconda3/lib/python3.12/site-packages/dspy/utils/callback.py", line 326, in sync_wrapper\n    return fn(instance, *args, **kwargs)\n           ^^^^^^^^^^^^^^^^^^^^^^^^^^^^^\nTypeError: Tool.__call__() got multiple values for argument \'self\'', 'thought_1': 'It seems there was an execution error in the PythonInterpreter. I will try to reformat the code to ensure it runs correctly. I will also ensure that the variables are properly defined and that the code is structured correctly for execution.', 'tool_name_1': 'PythonInterpreter', 'tool_args_1': {'self': {}, 'code': 'total_budget = 10000\nnum_depts = 3\nactual_allocation_dept3 = 5000\nexpected_share_per_dept = total_budget / num_depts\ndeviation_dept3 = expected_share_per_dept - actual_allocation_dept3\nround(deviation_dept3, 2)', 'variables': {}}, 'observation_1': 'Execution error in PythonInterpreter: \nTraceback (most recent call last):\n  File "/opt/anaconda3/lib/python3.12/site-packages/dspy/predict/react.py", line 89, in forward\n    trajectory[f"observation_{idx}"] = self.tools[pred.next_tool_name](**pred.next_tool_args)\n                                       ^^^^^^^^^^^^^^^^^^^^^^^^^^^^^^^^^^^^^^^^^^^^^^^^^^^^^^\n  File "/opt/anaconda3/lib/python3.12/site-packages/dspy/utils/callback.py", line 326, in sync_wrapper\n    return fn(instance, *args, **kwargs)\n           ^^^^^^^^^^^^^^^^^^^^^^^^^^^^^\nTypeError: Tool.__call__() got multiple values for argument \'self\'', 'thought_2': 'It appears that there is a persistent execution error with the PythonInterpreter. I will simplify the code to ensure it runs correctly. I will also check if the code can be executed in a more straightforward manner without any complex structures.', 'tool_name_2': 'PythonInterpreter', 'tool_args_2': {'self': {}, 'code': 'expected_share_per_dept = 10000 / 3\nactual_allocation_dept3 = 5000\ndeviation_dept3 = expected_share_per_dept - actual_allocation_dept3\nround(deviation_dept3, 2)', 'variables': {}}, 'observation_2': 'Execution error in PythonInterpreter: \nTraceback (most recent call last):\n  File "/opt/anaconda3/lib/python3.12/site-packages/dspy/predict/react.py", line 89, in forward\n    trajectory[f"observation_{idx}"] = self.tools[pred.next_tool_name](**pred.next_tool_args)\n                                       ^^^^^^^^^^^^^^^^^^^^^^^^^^^^^^^^^^^^^^^^^^^^^^^^^^^^^^\n  File "/opt/anaconda3/lib/python3.12/site-packages/dspy/utils/callback.py", line 326, in sync_wrapper\n    return fn(instance, *args, **kwargs)\n           ^^^^^^^^^^^^^^^^^^^^^^^^^^^^^\nTypeError: Tool.__call__() got multiple values for argument \'self\'', 'thought_3': 'The PythonInterpreter is consistently returning an execution error, which suggests that there may be an issue with how the tool is being called. I will attempt to run a simpler calculation directly without any variable assignments to see if that resolves the issue. I will compute the expected share and the deviation in a single line.', 'tool_name_3': 'PythonInterpreter', 'tool_args_3': {'self': {}, 'code': 'round((10000 / 3) - 5000, 2)', 'variables': {}}, 'observation_3': 'Execution error in PythonInterpreter: \nTraceback (most recent call last):\n  File "/opt/anaconda3/lib/python3.12/site-packages/dspy/predict/react.py", line 89, in forward\n    trajectory[f"observation_{idx}"] = self.tools[pred.next_tool_name](**pred.next_tool_args)\n                                       ^^^^^^^^^^^^^^^^^^^^^^^^^^^^^^^^^^^^^^^^^^^^^^^^^^^^^^\n  File "/opt/anaconda3/lib/python3.12/site-packages/dspy/utils/callback.py", line 326, in sync_wrapper\n    return fn(instance, *args, **kwargs)\n           ^^^^^^^^^^^^^^^^^^^^^^^^^^^^^\nTypeError: Tool.__call__() got multiple values for argument \'self\'', 'thought_4': 'The PythonInterpreter is consistently returning an execution error, indicating a potential issue with how the tool is being invoked. I will try a different approach by simplifying the calculation further and ensuring that the code is as straightforward as possible. I will compute the expected share and the deviation in a single line without any variable assignments.', 'tool_name_4': 'PythonInterpreter', 'tool_args_4': {'self': {}, 'code': 'round((10000 / 3) - 5000, 2)', 'variables': {}}, 'observation_4': 'Execution error in PythonInterpreter: \nTraceback (most recent call last):\n  File "/opt/anaconda3/lib/python3.12/site-packages/dspy/predict/react.py", line 89, in forward\n    trajectory[f"observation_{idx}"] = self.tools[pred.next_tool_name](**pred.next_tool_args)\n                                       ^^^^^^^^^^^^^^^^^^^^^^^^^^^^^^^^^^^^^^^^^^^^^^^^^^^^^^\n  File "/opt/anaconda3/lib/python3.12/site-packages/dspy/utils/callback.py", line 326, in sync_wrapper\n    return fn(instance, *args, **kwargs)\n           ^^^^^^^^^^^^^^^^^^^^^^^^^^^^^\nTypeError: Tool.__call__() got multiple values for argument \'self\''},
    reasoning='To find the deviation for Dept3, I need to first calculate the expected share per department by dividing the total budget of $10,000 by the number of departments, which is 3. This gives me the expected share for each department. Then, I will subtract the actual allocation for Dept3, which is $5,000, from this expected share to find the deviation. Finally, I will round the result to two decimal places.',
    thought='The calculation involves basic arithmetic: dividing the total budget by the number of departments to get the expected share, and then subtracting the actual allocation for Dept3 from this expected share. The expected share per department is $3,333.33, and the deviation for Dept3 is calculated as $3,333.33 - $5,000. The result will be negative, indicating that Dept3 received more than its expected share.',
    answer='-1666.67'
)
ðŸ”´ FAILED
reasoning: subtracted in the wrong order

Example 16:
Input: {'number1': 'The dataset contains values: 2, 5, 8, 11, 14', 'number2': 'Ignore the smallest and largest values', 'function': 'Compute average of middle three values only. Round to 1 decimal.'}
Expected: 8.0
Result: Prediction(
    trajectory={'thought_0': 'To compute the average of the middle three values from the dataset, I will first extract the values, ignore the smallest (2) and largest (14), and then calculate the average of the remaining values (5, 8, 11). I will round the result to one decimal place.', 'tool_name_0': 'PythonInterpreter', 'tool_args_0': {'self': {}, 'code': 'values = [2, 5, 8, 11, 14]\n# Ignore the smallest and largest values\nmiddle_values = sorted(values)[1:-1]\n# Calculate the average of the middle three values\naverage = sum(middle_values) / len(middle_values)\n# Round to 1 decimal place\nrounded_average = round(average, 1)\nrounded_average', 'variables': {}}, 'observation_0': 'Execution error in PythonInterpreter: \nTraceback (most recent call last):\n  File "/opt/anaconda3/lib/python3.12/site-packages/dspy/predict/react.py", line 89, in forward\n    trajectory[f"observation_{idx}"] = self.tools[pred.next_tool_name](**pred.next_tool_args)\n                                       ^^^^^^^^^^^^^^^^^^^^^^^^^^^^^^^^^^^^^^^^^^^^^^^^^^^^^^\n  File "/opt/anaconda3/lib/python3.12/site-packages/dspy/utils/callback.py", line 326, in sync_wrapper\n    return fn(instance, *args, **kwargs)\n           ^^^^^^^^^^^^^^^^^^^^^^^^^^^^^\nTypeError: Tool.__call__() got multiple values for argument \'self\'', 'thought_1': 'It seems there was an execution error in the PythonInterpreter due to a conflict with the arguments. I will adjust the code to ensure it runs correctly. The logic remains the same: I will extract the middle three values from the dataset and compute their average, rounding to one decimal place.', 'tool_name_1': 'PythonInterpreter', 'tool_args_1': {'self': {}, 'code': 'values = [2, 5, 8, 11, 14]\n# Ignore the smallest and largest values\nmiddle_values = values[1:4]\n# Calculate the average of the middle three values\naverage = sum(middle_values) / len(middle_values)\n# Round to 1 decimal place\nrounded_average = round(average, 1)\nrounded_average', 'variables': {}}, 'observation_1': 'Execution error in PythonInterpreter: \nTraceback (most recent call last):\n  File "/opt/anaconda3/lib/python3.12/site-packages/dspy/predict/react.py", line 89, in forward\n    trajectory[f"observation_{idx}"] = self.tools[pred.next_tool_name](**pred.next_tool_args)\n                                       ^^^^^^^^^^^^^^^^^^^^^^^^^^^^^^^^^^^^^^^^^^^^^^^^^^^^^^\n  File "/opt/anaconda3/lib/python3.12/site-packages/dspy/utils/callback.py", line 326, in sync_wrapper\n    return fn(instance, *args, **kwargs)\n           ^^^^^^^^^^^^^^^^^^^^^^^^^^^^^\nTypeError: Tool.__call__() got multiple values for argument \'self\'', 'thought_2': 'It appears that there is a persistent issue with executing the code in the PythonInterpreter. I will simplify the approach by directly calculating the average of the middle three values without using a list comprehension. I will also ensure that the code is structured correctly to avoid any argument conflicts.', 'tool_name_2': 'PythonInterpreter', 'tool_args_2': {'self': {}, 'code': 'values = [2, 5, 8, 11, 14]\n# Ignore the smallest and largest values\nmiddle_values = [5, 8, 11]\n# Calculate the average of the middle three values\naverage = sum(middle_values) / len(middle_values)\n# Round to 1 decimal place\nrounded_average = round(average, 1)\nrounded_average', 'variables': {}}, 'observation_2': 'Execution error in PythonInterpreter: \nTraceback (most recent call last):\n  File "/opt/anaconda3/lib/python3.12/site-packages/dspy/predict/react.py", line 89, in forward\n    trajectory[f"observation_{idx}"] = self.tools[pred.next_tool_name](**pred.next_tool_args)\n                                       ^^^^^^^^^^^^^^^^^^^^^^^^^^^^^^^^^^^^^^^^^^^^^^^^^^^^^^\n  File "/opt/anaconda3/lib/python3.12/site-packages/dspy/utils/callback.py", line 326, in sync_wrapper\n    return fn(instance, *args, **kwargs)\n           ^^^^^^^^^^^^^^^^^^^^^^^^^^^^^\nTypeError: Tool.__call__() got multiple values for argument \'self\'', 'thought_3': 'The PythonInterpreter is encountering a persistent issue with executing the code. I will try a different approach by simplifying the code further and ensuring that I am not using any unnecessary complexity. I will directly calculate the average of the middle three values (5, 8, 11) and round the result to one decimal place.', 'tool_name_3': 'PythonInterpreter', 'tool_args_3': {'self': {}, 'code': 'middle_values = [5, 8, 11]\n# Calculate the average of the middle three values\naverage = sum(middle_values) / len(middle_values)\n# Round to 1 decimal place\nrounded_average = round(average, 1)\nrounded_average', 'variables': {}}, 'observation_3': 'Execution error in PythonInterpreter: \nTraceback (most recent call last):\n  File "/opt/anaconda3/lib/python3.12/site-packages/dspy/predict/react.py", line 89, in forward\n    trajectory[f"observation_{idx}"] = self.tools[pred.next_tool_name](**pred.next_tool_args)\n                                       ^^^^^^^^^^^^^^^^^^^^^^^^^^^^^^^^^^^^^^^^^^^^^^^^^^^^^^\n  File "/opt/anaconda3/lib/python3.12/site-packages/dspy/utils/callback.py", line 326, in sync_wrapper\n    return fn(instance, *args, **kwargs)\n           ^^^^^^^^^^^^^^^^^^^^^^^^^^^^^\nTypeError: Tool.__call__() got multiple values for argument \'self\'', 'thought_4': 'The PythonInterpreter is consistently failing to execute the code due to an argument conflict. I will switch to a different approach by manually calculating the average of the middle three values (5, 8, 11) without relying on the interpreter. The average can be calculated as (5 + 8 + 11) / 3, and I will round the result to one decimal place.', 'tool_name_4': 'finish', 'tool_args_4': {}, 'observation_4': 'Completed.'},
    reasoning='To compute the average of the middle three values from the dataset, I first identified the values to consider. The dataset contains the values 2, 5, 8, 11, and 14. By ignoring the smallest (2) and largest (14) values, the remaining values are 5, 8, and 11. The average of these three values is calculated by summing them up and dividing by the count of the values, which is 3. Finally, I round the result to one decimal place.',
    thought='I manually calculated the average of the middle three values (5, 8, 11) as (5 + 8 + 11) / 3 = 8.0. This approach bypassed the issues encountered with the PythonInterpreter, ensuring that I could provide a correct answer.',
    answer='8.0'
)
ðŸŸ¢ PASSED

Example 17:
Input: {'number1': 'This year: 780 people attended. Last year: 620.', 'number2': 'Target growth was 20%', 'function': 'Calculate actual percent increase from last year to this year, then subtract target growth. Round to 1 decimal.'}
Expected: 5.8
Result: Prediction(
    trajectory={'thought_0': "To calculate the actual percent increase from last year to this year, I will first determine the increase in attendance, which is the difference between this year's and last year's attendance. Then, I will calculate the percent increase based on last year's attendance. After that, I will subtract the target growth of 20% from the actual percent increase and round the result to one decimal place.", 'tool_name_0': 'PythonInterpreter', 'tool_args_0': {'self': {}, 'code': 'last_year_attendance = 620\nthis_year_attendance = 780\nincrease = this_year_attendance - last_year_attendance\npercent_increase = (increase / last_year_attendance) * 100\ntarget_growth = 20\nresult = round(percent_increase - target_growth, 1)\nresult', 'variables': {}}, 'observation_0': 'Execution error in PythonInterpreter: \nTraceback (most recent call last):\n  File "/opt/anaconda3/lib/python3.12/site-packages/dspy/predict/react.py", line 89, in forward\n    trajectory[f"observation_{idx}"] = self.tools[pred.next_tool_name](**pred.next_tool_args)\n                                       ^^^^^^^^^^^^^^^^^^^^^^^^^^^^^^^^^^^^^^^^^^^^^^^^^^^^^^\n  File "/opt/anaconda3/lib/python3.12/site-packages/dspy/utils/callback.py", line 326, in sync_wrapper\n    return fn(instance, *args, **kwargs)\n           ^^^^^^^^^^^^^^^^^^^^^^^^^^^^^\nTypeError: Tool.__call__() got multiple values for argument \'self\'', 'thought_1': 'It seems there was an execution error in the PythonInterpreter. I will adjust the code to ensure it runs correctly. I will also make sure to define the variables properly and check for any potential issues in the code structure.', 'tool_name_1': 'PythonInterpreter', 'tool_args_1': {'self': {}, 'code': 'last_year_attendance = 620\nthis_year_attendance = 780\nincrease = this_year_attendance - last_year_attendance\npercent_increase = (increase / last_year_attendance) * 100\ntarget_growth = 20\nresult = round(percent_increase - target_growth, 1)\nresult', 'variables': {}}, 'observation_1': 'Execution error in PythonInterpreter: \nTraceback (most recent call last):\n  File "/opt/anaconda3/lib/python3.12/site-packages/dspy/predict/react.py", line 89, in forward\n    trajectory[f"observation_{idx}"] = self.tools[pred.next_tool_name](**pred.next_tool_args)\n                                       ^^^^^^^^^^^^^^^^^^^^^^^^^^^^^^^^^^^^^^^^^^^^^^^^^^^^^^\n  File "/opt/anaconda3/lib/python3.12/site-packages/dspy/utils/callback.py", line 326, in sync_wrapper\n    return fn(instance, *args, **kwargs)\n           ^^^^^^^^^^^^^^^^^^^^^^^^^^^^^\nTypeError: Tool.__call__() got multiple values for argument \'self\'', 'thought_2': 'It appears that there is a persistent execution error with the PythonInterpreter. I will simplify the code and ensure that it is structured correctly to avoid any issues. I will also check if there are any unnecessary parameters being passed that could be causing the error.', 'tool_name_2': 'PythonInterpreter', 'tool_args_2': {'self': {}, 'code': 'last_year_attendance = 620\nthis_year_attendance = 780\nincrease = this_year_attendance - last_year_attendance\npercent_increase = (increase / last_year_attendance) * 100\ntarget_growth = 20\nresult = round(percent_increase - target_growth, 1)\nresult', 'variables': {}}, 'observation_2': 'Execution error in PythonInterpreter: \nTraceback (most recent call last):\n  File "/opt/anaconda3/lib/python3.12/site-packages/dspy/predict/react.py", line 89, in forward\n    trajectory[f"observation_{idx}"] = self.tools[pred.next_tool_name](**pred.next_tool_args)\n                                       ^^^^^^^^^^^^^^^^^^^^^^^^^^^^^^^^^^^^^^^^^^^^^^^^^^^^^^\n  File "/opt/anaconda3/lib/python3.12/site-packages/dspy/utils/callback.py", line 326, in sync_wrapper\n    return fn(instance, *args, **kwargs)\n           ^^^^^^^^^^^^^^^^^^^^^^^^^^^^^\nTypeError: Tool.__call__() got multiple values for argument \'self\'', 'thought_3': 'The PythonInterpreter is consistently returning an execution error, which suggests that there may be an issue with how the code is being executed or the parameters being passed. I will try a different approach by simplifying the code further and ensuring that I only pass the necessary parameters. I will also check if there are any syntax issues that could be causing the problem.', 'tool_name_3': 'PythonInterpreter', 'tool_args_3': {'self': {}, 'code': 'last_year_attendance = 620\nthis_year_attendance = 780\nincrease = this_year_attendance - last_year_attendance\npercent_increase = (increase / last_year_attendance) * 100\ntarget_growth = 20\nresult = round(percent_increase - target_growth, 1)\nresult', 'variables': {}}, 'observation_3': 'Execution error in PythonInterpreter: \nTraceback (most recent call last):\n  File "/opt/anaconda3/lib/python3.12/site-packages/dspy/predict/react.py", line 89, in forward\n    trajectory[f"observation_{idx}"] = self.tools[pred.next_tool_name](**pred.next_tool_args)\n                                       ^^^^^^^^^^^^^^^^^^^^^^^^^^^^^^^^^^^^^^^^^^^^^^^^^^^^^^\n  File "/opt/anaconda3/lib/python3.12/site-packages/dspy/utils/callback.py", line 326, in sync_wrapper\n    return fn(instance, *args, **kwargs)\n           ^^^^^^^^^^^^^^^^^^^^^^^^^^^^^\nTypeError: Tool.__call__() got multiple values for argument \'self\'', 'thought_4': 'The PythonInterpreter is consistently returning an execution error, indicating a potential issue with how the code is structured or executed. I will try to run a simpler version of the code that calculates the actual percent increase and subtracts the target growth without any additional complexity. This should help in identifying if the issue lies within the code or the execution environment.', 'tool_name_4': 'PythonInterpreter', 'tool_args_4': {'self': {}, 'code': 'last_year_attendance = 620\nthis_year_attendance = 780\npercent_increase = round(((this_year_attendance - last_year_attendance) / last_year_attendance) * 100 - 20, 1)\npercent_increase', 'variables': {}}, 'observation_4': 'Execution error in PythonInterpreter: \nTraceback (most recent call last):\n  File "/opt/anaconda3/lib/python3.12/site-packages/dspy/predict/react.py", line 89, in forward\n    trajectory[f"observation_{idx}"] = self.tools[pred.next_tool_name](**pred.next_tool_args)\n                                       ^^^^^^^^^^^^^^^^^^^^^^^^^^^^^^^^^^^^^^^^^^^^^^^^^^^^^^\n  File "/opt/anaconda3/lib/python3.12/site-packages/dspy/utils/callback.py", line 326, in sync_wrapper\n    return fn(instance, *args, **kwargs)\n           ^^^^^^^^^^^^^^^^^^^^^^^^^^^^^\nTypeError: Tool.__call__() got multiple values for argument \'self\''},
    reasoning="To find the actual percent increase in attendance from last year to this year, I first calculate the increase in attendance by subtracting last year's attendance (620) from this year's attendance (780). This gives us an increase of 160 people. Next, I calculate the percent increase by dividing the increase (160) by last year's attendance (620) and multiplying by 100. This results in an actual percent increase. Finally, I subtract the target growth of 20% from the actual percent increase and round the result to one decimal place.",
    thought='The calculations involve basic arithmetic operations: subtraction to find the increase, division to find the percent increase, and rounding to format the final answer. I will ensure that the calculations are straightforward and correctly reflect the required operations.',
    answer='The actual percent increase is approximately 25.8%. After subtracting the target growth of 20%, the final result is 5.8%.'
)
ðŸ”´ FAILED
reasoning: correct answer, not presented in expected way

Example 18:
Input: {'number1': 'Monthly expenses: Jan: 950, Feb: 1020, Mar: 875', 'number2': 'April budget ceiling is 1000', 'function': 'Find average of the first three months. Subtract April budget. Round to 1 decimal.'}
Expected: -15.0
Result: Prediction(
    trajectory={'thought_0': 'To find the average of the monthly expenses for January, February, and March, I will first calculate the total expenses for these three months and then divide by 3. After obtaining the average, I will subtract the April budget ceiling of 1000 from this average and round the result to one decimal place.', 'tool_name_0': 'PythonInterpreter', 'tool_args_0': {'self': {}, 'code': 'jan = 950\nfeb = 1020\nmar = 875\naverage_expenses = (jan + feb + mar) / 3\nresult = round(average_expenses - 1000, 1)\nresult', 'variables': {}}, 'observation_0': 'Execution error in PythonInterpreter: \nTraceback (most recent call last):\n  File "/opt/anaconda3/lib/python3.12/site-packages/dspy/predict/react.py", line 89, in forward\n    trajectory[f"observation_{idx}"] = self.tools[pred.next_tool_name](**pred.next_tool_args)\n                                       ^^^^^^^^^^^^^^^^^^^^^^^^^^^^^^^^^^^^^^^^^^^^^^^^^^^^^^\n  File "/opt/anaconda3/lib/python3.12/site-packages/dspy/utils/callback.py", line 326, in sync_wrapper\n    return fn(instance, *args, **kwargs)\n           ^^^^^^^^^^^^^^^^^^^^^^^^^^^^^\nTypeError: Tool.__call__() got multiple values for argument \'self\'', 'thought_1': 'It seems there was an execution error in the PythonInterpreter due to a misconfiguration in the arguments. I will correct the code to ensure it runs properly. I will also ensure that the calculation for the average and the subtraction of the April budget ceiling is done correctly.', 'tool_name_1': 'PythonInterpreter', 'tool_args_1': {'self': {}, 'code': 'jan = 950\nfeb = 1020\nmar = 875\naverage_expenses = (jan + feb + mar) / 3\nresult = round(average_expenses - 1000, 1)\nresult', 'variables': {}}, 'observation_1': 'Execution error in PythonInterpreter: \nTraceback (most recent call last):\n  File "/opt/anaconda3/lib/python3.12/site-packages/dspy/predict/react.py", line 89, in forward\n    trajectory[f"observation_{idx}"] = self.tools[pred.next_tool_name](**pred.next_tool_args)\n                                       ^^^^^^^^^^^^^^^^^^^^^^^^^^^^^^^^^^^^^^^^^^^^^^^^^^^^^^\n  File "/opt/anaconda3/lib/python3.12/site-packages/dspy/utils/callback.py", line 326, in sync_wrapper\n    return fn(instance, *args, **kwargs)\n           ^^^^^^^^^^^^^^^^^^^^^^^^^^^^^\nTypeError: Tool.__call__() got multiple values for argument \'self\'', 'thought_2': 'It appears that there is a persistent issue with the execution of the PythonInterpreter due to argument misconfiguration. I will simplify the code and ensure that it is structured correctly to avoid any errors. I will also check if the environment requires any specific adjustments for the execution.', 'tool_name_2': 'PythonInterpreter', 'tool_args_2': {'self': {}, 'code': 'jan, feb, mar = 950, 1020, 875\naverage_expenses = (jan + feb + mar) / 3\nresult = round(average_expenses - 1000, 1)\nresult', 'variables': {}}, 'observation_2': 'Execution error in PythonInterpreter: \nTraceback (most recent call last):\n  File "/opt/anaconda3/lib/python3.12/site-packages/dspy/predict/react.py", line 89, in forward\n    trajectory[f"observation_{idx}"] = self.tools[pred.next_tool_name](**pred.next_tool_args)\n                                       ^^^^^^^^^^^^^^^^^^^^^^^^^^^^^^^^^^^^^^^^^^^^^^^^^^^^^^\n  File "/opt/anaconda3/lib/python3.12/site-packages/dspy/utils/callback.py", line 326, in sync_wrapper\n    return fn(instance, *args, **kwargs)\n           ^^^^^^^^^^^^^^^^^^^^^^^^^^^^^\nTypeError: Tool.__call__() got multiple values for argument \'self\'', 'thought_3': 'It seems that there is a consistent issue with executing the PythonInterpreter due to argument misconfiguration. I will attempt to run a simpler calculation directly in the code to ensure that the environment is functioning correctly. I will calculate the average expenses and the final result in a single step to avoid any potential issues with variable assignments.', 'tool_name_3': 'PythonInterpreter', 'tool_args_3': {'self': {}, 'code': 'average_expenses = (950 + 1020 + 875) / 3\nresult = round(average_expenses - 1000, 1)\nresult', 'variables': {}}, 'observation_3': 'Execution error in PythonInterpreter: \nTraceback (most recent call last):\n  File "/opt/anaconda3/lib/python3.12/site-packages/dspy/predict/react.py", line 89, in forward\n    trajectory[f"observation_{idx}"] = self.tools[pred.next_tool_name](**pred.next_tool_args)\n                                       ^^^^^^^^^^^^^^^^^^^^^^^^^^^^^^^^^^^^^^^^^^^^^^^^^^^^^^\n  File "/opt/anaconda3/lib/python3.12/site-packages/dspy/utils/callback.py", line 326, in sync_wrapper\n    return fn(instance, *args, **kwargs)\n           ^^^^^^^^^^^^^^^^^^^^^^^^^^^^^\nTypeError: Tool.__call__() got multiple values for argument \'self\'', 'thought_4': 'The PythonInterpreter is consistently failing to execute the code due to a misconfiguration. I will switch to a different approach by calculating the average and the final result manually without relying on the interpreter. I will compute the average of the expenses for January, February, and March, then subtract the April budget ceiling, and round the result to one decimal place.', 'tool_name_4': 'finish', 'tool_args_4': {}, 'observation_4': 'Completed.'},
    reasoning='To find the average of the monthly expenses for January, February, and March, I first calculated the total expenses for these three months: 950 + 1020 + 875 = 2845. Then, I divided this total by 3 to find the average, which is 2845 / 3 = 948.33. After obtaining the average, I subtracted the April budget ceiling of 1000 from this average: 948.33 - 1000 = -51.67. Finally, I rounded the result to one decimal place, which gives -51.7.',
    thought='The thought process involved calculating the total expenses for the first three months, finding the average, and then subtracting the April budget ceiling. I ensured to round the final result to one decimal place as required.',
    answer='-51.7'
)
ðŸ”´ FAILED

Example 19:
Input: {'number1': 'Student scores: 95, 86, 92, 88, 100', 'number2': 'Only keep top 3 scores', 'function': 'Compute average of the top 3 scores. Round to 1 decimal.'}
Expected: 95.7
Result: Prediction(
    trajectory={'thought_0': 'To compute the average of the top 3 scores from the given student scores, I will first sort the scores in descending order, select the top 3 scores, and then calculate their average. Finally, I will round the result to one decimal place.', 'tool_name_0': 'PythonInterpreter', 'tool_args_0': {'self': {}, 'code': 'scores = [95, 86, 92, 88, 100]\ntop_scores = sorted(scores, reverse=True)[:3]\naverage_top_scores = round(sum(top_scores) / len(top_scores), 1)\naverage_top_scores', 'variables': None}, 'observation_0': 'Execution error in PythonInterpreter: \nTraceback (most recent call last):\n  File "/opt/anaconda3/lib/python3.12/site-packages/dspy/predict/react.py", line 89, in forward\n    trajectory[f"observation_{idx}"] = self.tools[pred.next_tool_name](**pred.next_tool_args)\n                                       ^^^^^^^^^^^^^^^^^^^^^^^^^^^^^^^^^^^^^^^^^^^^^^^^^^^^^^\n  File "/opt/anaconda3/lib/python3.12/site-packages/dspy/utils/callback.py", line 326, in sync_wrapper\n    return fn(instance, *args, **kwargs)\n           ^^^^^^^^^^^^^^^^^^^^^^^^^^^^^\nTypeError: Tool.__call__() got multiple values for argument \'self\'', 'thought_1': 'It seems there was an execution error in the PythonInterpreter. I will try to run the code again, ensuring that the arguments are correctly formatted. The logic remains the same: sort the scores, select the top 3, and compute the average rounded to one decimal place.', 'tool_name_1': 'PythonInterpreter', 'tool_args_1': {'code': 'scores = [95, 86, 92, 88, 100]\ntop_scores = sorted(scores, reverse=True)[:3]\naverage_top_scores = round(sum(top_scores) / len(top_scores), 1)\naverage_top_scores', 'variables': None}, 'observation_1': 'Execution error in PythonInterpreter: \nTraceback (most recent call last):\n  File "/opt/anaconda3/lib/python3.12/site-packages/dspy/predict/react.py", line 89, in forward\n    trajectory[f"observation_{idx}"] = self.tools[pred.next_tool_name](**pred.next_tool_args)\n                                       ^^^^^^^^^^^^^^^^^^^^^^^^^^^^^^^^^^^^^^^^^^^^^^^^^^^^^^\n  File "/opt/anaconda3/lib/python3.12/site-packages/dspy/utils/callback.py", line 326, in sync_wrapper\n    return fn(instance, *args, **kwargs)\n           ^^^^^^^^^^^^^^^^^^^^^^^^^^^^^\n  File "/opt/anaconda3/lib/python3.12/site-packages/dspy/adapters/types/tool.py", line 166, in __call__\n    result = self.func(**parsed_kwargs)\n             ^^^^^^^^^^^^^^^^^^^^^^^^^^\nTypeError: PythonInterpreter.__init__() got an unexpected keyword argument \'code\'', 'thought_2': 'It appears that there is an issue with how the PythonInterpreter is being called. I will adjust the code execution to ensure it runs correctly. I will also simplify the code to avoid any potential issues with the arguments.', 'tool_name_2': 'PythonInterpreter', 'tool_args_2': {'code': 'scores = [95, 86, 92, 88, 100]\ntop_scores = sorted(scores, reverse=True)[:3]\naverage_top_scores = round(sum(top_scores) / len(top_scores), 1)\naverage_top_scores', 'variables': None}, 'observation_2': 'Execution error in PythonInterpreter: \nTraceback (most recent call last):\n  File "/opt/anaconda3/lib/python3.12/site-packages/dspy/predict/react.py", line 89, in forward\n    trajectory[f"observation_{idx}"] = self.tools[pred.next_tool_name](**pred.next_tool_args)\n                                       ^^^^^^^^^^^^^^^^^^^^^^^^^^^^^^^^^^^^^^^^^^^^^^^^^^^^^^\n  File "/opt/anaconda3/lib/python3.12/site-packages/dspy/utils/callback.py", line 326, in sync_wrapper\n    return fn(instance, *args, **kwargs)\n           ^^^^^^^^^^^^^^^^^^^^^^^^^^^^^\n  File "/opt/anaconda3/lib/python3.12/site-packages/dspy/adapters/types/tool.py", line 166, in __call__\n    result = self.func(**parsed_kwargs)\n             ^^^^^^^^^^^^^^^^^^^^^^^^^^\nTypeError: PythonInterpreter.__init__() got an unexpected keyword argument \'code\'', 'thought_3': 'It seems there is a persistent issue with executing the code in the PythonInterpreter. I will try a different approach by simplifying the code execution and ensuring that the arguments are correctly formatted. I will also check if there are any syntax issues that might be causing the errors.', 'tool_name_3': 'PythonInterpreter', 'tool_args_3': {'code': 'scores = [95, 86, 92, 88, 100]\ntop_scores = sorted(scores, reverse=True)[:3]\naverage_top_scores = round(sum(top_scores) / 3, 1)\naverage_top_scores', 'variables': None}, 'observation_3': 'Execution error in PythonInterpreter: \nTraceback (most recent call last):\n  File "/opt/anaconda3/lib/python3.12/site-packages/dspy/predict/react.py", line 89, in forward\n    trajectory[f"observation_{idx}"] = self.tools[pred.next_tool_name](**pred.next_tool_args)\n                                       ^^^^^^^^^^^^^^^^^^^^^^^^^^^^^^^^^^^^^^^^^^^^^^^^^^^^^^\n  File "/opt/anaconda3/lib/python3.12/site-packages/dspy/utils/callback.py", line 326, in sync_wrapper\n    return fn(instance, *args, **kwargs)\n           ^^^^^^^^^^^^^^^^^^^^^^^^^^^^^\n  File "/opt/anaconda3/lib/python3.12/site-packages/dspy/adapters/types/tool.py", line 166, in __call__\n    result = self.func(**parsed_kwargs)\n             ^^^^^^^^^^^^^^^^^^^^^^^^^^\nTypeError: PythonInterpreter.__init__() got an unexpected keyword argument \'code\'', 'thought_4': 'It seems that there is a consistent issue with executing the code in the PythonInterpreter. I will try to simplify the code further and ensure that the arguments are correctly formatted. I will also check if there are any syntax issues that might be causing the errors. I will attempt to run a basic calculation to see if the interpreter is functioning correctly.', 'tool_name_4': 'PythonInterpreter', 'tool_args_4': {'code': 'scores = [95, 86, 92, 88, 100]\ntop_scores = sorted(scores, reverse=True)[:3]\naverage_top_scores = round(sum(top_scores) / len(top_scores), 1)\naverage_top_scores', 'variables': None}, 'observation_4': 'Execution error in PythonInterpreter: \nTraceback (most recent call last):\n  File "/opt/anaconda3/lib/python3.12/site-packages/dspy/predict/react.py", line 89, in forward\n    trajectory[f"observation_{idx}"] = self.tools[pred.next_tool_name](**pred.next_tool_args)\n                                       ^^^^^^^^^^^^^^^^^^^^^^^^^^^^^^^^^^^^^^^^^^^^^^^^^^^^^^\n  File "/opt/anaconda3/lib/python3.12/site-packages/dspy/utils/callback.py", line 326, in sync_wrapper\n    return fn(instance, *args, **kwargs)\n           ^^^^^^^^^^^^^^^^^^^^^^^^^^^^^\n  File "/opt/anaconda3/lib/python3.12/site-packages/dspy/adapters/types/tool.py", line 166, in __call__\n    result = self.func(**parsed_kwargs)\n             ^^^^^^^^^^^^^^^^^^^^^^^^^^\nTypeError: PythonInterpreter.__init__() got an unexpected keyword argument \'code\''},
    reasoning='To compute the average of the top 3 scores from the given student scores, I will first sort the scores in descending order, select the top 3 scores, and then calculate their average. Finally, I will round the result to one decimal place.',
    thought='The scores provided are [95, 86, 92, 88, 100]. After sorting these scores in descending order, the top 3 scores are 100, 95, and 92. The average of these scores can be calculated as (100 + 95 + 92) / 3, which equals 95.7 when rounded to one decimal place.',
    answer='95.7'
)
ðŸŸ¢ PASSED

Example 20:
Input: {'number1': 'Initial value: 1200, increase: 300', 'number2': 'Then decreased by 10% of new value', 'function': 'Add increase, then subtract 10% of the result. Round to nearest whole number.'}
Expected: 1350
Result: Prediction(
    trajectory={'thought_0': 'To solve the problem, I need to first add the increase of 300 to the initial value of 1200. This will give me a new value. Then, I will calculate 10% of this new value and subtract it from the new value. Finally, I will round the result to the nearest whole number. I will use the PythonInterpreter to perform these calculations.', 'tool_name_0': 'PythonInterpreter', 'tool_args_0': {'self': {}, 'code': 'initial_value = 1200\nincrease = 300\nnew_value = initial_value + increase\nreduction = new_value * 0.10\nfinal_value = new_value - reduction\nrounded_result = round(final_value)\nrounded_result', 'variables': None}, 'observation_0': 'Execution error in PythonInterpreter: \nTraceback (most recent call last):\n  File "/opt/anaconda3/lib/python3.12/site-packages/dspy/predict/react.py", line 89, in forward\n    trajectory[f"observation_{idx}"] = self.tools[pred.next_tool_name](**pred.next_tool_args)\n                                       ^^^^^^^^^^^^^^^^^^^^^^^^^^^^^^^^^^^^^^^^^^^^^^^^^^^^^^\n  File "/opt/anaconda3/lib/python3.12/site-packages/dspy/utils/callback.py", line 326, in sync_wrapper\n    return fn(instance, *args, **kwargs)\n           ^^^^^^^^^^^^^^^^^^^^^^^^^^^^^\nTypeError: Tool.__call__() got multiple values for argument \'self\'', 'thought_1': 'It seems there was an execution error in the PythonInterpreter due to a parameter issue. I will correct the code and try again. The logic remains the same: add the increase to the initial value, calculate 10% of the new value, subtract that from the new value, and round the result. I will ensure the code is formatted correctly for execution.', 'tool_name_1': 'PythonInterpreter', 'tool_args_1': {'self': {}, 'code': 'initial_value = 1200\nincrease = 300\nnew_value = initial_value + increase\nreduction = new_value * 0.10\nfinal_value = new_value - reduction\nrounded_result = round(final_value)\nrounded_result', 'variables': None}, 'observation_1': 'Execution error in PythonInterpreter: \nTraceback (most recent call last):\n  File "/opt/anaconda3/lib/python3.12/site-packages/dspy/predict/react.py", line 89, in forward\n    trajectory[f"observation_{idx}"] = self.tools[pred.next_tool_name](**pred.next_tool_args)\n                                       ^^^^^^^^^^^^^^^^^^^^^^^^^^^^^^^^^^^^^^^^^^^^^^^^^^^^^^\n  File "/opt/anaconda3/lib/python3.12/site-packages/dspy/utils/callback.py", line 326, in sync_wrapper\n    return fn(instance, *args, **kwargs)\n           ^^^^^^^^^^^^^^^^^^^^^^^^^^^^^\nTypeError: Tool.__call__() got multiple values for argument \'self\'', 'thought_2': "I need to adjust the way I call the PythonInterpreter. It seems there is a conflict with the parameters. I will remove the 'self' parameter from the tool arguments and try executing the code again. The logic for the calculation remains unchanged.", 'tool_name_2': 'PythonInterpreter', 'tool_args_2': {'code': 'initial_value = 1200\nincrease = 300\nnew_value = initial_value + increase\nreduction = new_value * 0.10\nfinal_value = new_value - reduction\nrounded_result = round(final_value)\nrounded_result', 'variables': None}, 'observation_2': 'Execution error in PythonInterpreter: \nTraceback (most recent call last):\n  File "/opt/anaconda3/lib/python3.12/site-packages/dspy/predict/react.py", line 89, in forward\n    trajectory[f"observation_{idx}"] = self.tools[pred.next_tool_name](**pred.next_tool_args)\n                                       ^^^^^^^^^^^^^^^^^^^^^^^^^^^^^^^^^^^^^^^^^^^^^^^^^^^^^^\n  File "/opt/anaconda3/lib/python3.12/site-packages/dspy/utils/callback.py", line 326, in sync_wrapper\n    return fn(instance, *args, **kwargs)\n           ^^^^^^^^^^^^^^^^^^^^^^^^^^^^^\n  File "/opt/anaconda3/lib/python3.12/site-packages/dspy/adapters/types/tool.py", line 166, in __call__\n    result = self.func(**parsed_kwargs)\n             ^^^^^^^^^^^^^^^^^^^^^^^^^^\nTypeError: PythonInterpreter.__init__() got an unexpected keyword argument \'code\'', 'thought_3': 'It appears that there is a persistent issue with how I am calling the PythonInterpreter. I need to ensure that I am using the correct parameters for the tool. I will revise my approach and try to execute the calculation again without any unnecessary parameters. The logic for the calculation remains the same: add the increase to the initial value, calculate 10% of the new value, subtract that from the new value, and round the result.', 'tool_name_3': 'PythonInterpreter', 'tool_args_3': {'code': 'initial_value = 1200\nincrease = 300\nnew_value = initial_value + increase\nreduction = new_value * 0.10\nfinal_value = new_value - reduction\nrounded_result = round(final_value)\nrounded_result', 'variables': None}, 'observation_3': 'Execution error in PythonInterpreter: \nTraceback (most recent call last):\n  File "/opt/anaconda3/lib/python3.12/site-packages/dspy/predict/react.py", line 89, in forward\n    trajectory[f"observation_{idx}"] = self.tools[pred.next_tool_name](**pred.next_tool_args)\n                                       ^^^^^^^^^^^^^^^^^^^^^^^^^^^^^^^^^^^^^^^^^^^^^^^^^^^^^^\n  File "/opt/anaconda3/lib/python3.12/site-packages/dspy/utils/callback.py", line 326, in sync_wrapper\n    return fn(instance, *args, **kwargs)\n           ^^^^^^^^^^^^^^^^^^^^^^^^^^^^^\n  File "/opt/anaconda3/lib/python3.12/site-packages/dspy/adapters/types/tool.py", line 166, in __call__\n    result = self.func(**parsed_kwargs)\n             ^^^^^^^^^^^^^^^^^^^^^^^^^^\nTypeError: PythonInterpreter.__init__() got an unexpected keyword argument \'code\'', 'thought_4': 'It seems that I have been encountering issues with the way I am calling the PythonInterpreter. I will simplify my approach and ensure that I am using the correct parameters. I will try executing the calculation again, focusing on the logic: adding the increase to the initial value, calculating 10% of the new value, subtracting that from the new value, and rounding the result.', 'tool_name_4': 'PythonInterpreter', 'tool_args_4': {'code': 'initial_value = 1200\nincrease = 300\nnew_value = initial_value + increase\nreduction = new_value * 0.10\nfinal_value = new_value - reduction\nrounded_result = round(final_value)\nrounded_result', 'variables': None}, 'observation_4': 'Execution error in PythonInterpreter: \nTraceback (most recent call last):\n  File "/opt/anaconda3/lib/python3.12/site-packages/dspy/predict/react.py", line 89, in forward\n    trajectory[f"observation_{idx}"] = self.tools[pred.next_tool_name](**pred.next_tool_args)\n                                       ^^^^^^^^^^^^^^^^^^^^^^^^^^^^^^^^^^^^^^^^^^^^^^^^^^^^^^\n  File "/opt/anaconda3/lib/python3.12/site-packages/dspy/utils/callback.py", line 326, in sync_wrapper\n    return fn(instance, *args, **kwargs)\n           ^^^^^^^^^^^^^^^^^^^^^^^^^^^^^\n  File "/opt/anaconda3/lib/python3.12/site-packages/dspy/adapters/types/tool.py", line 166, in __call__\n    result = self.func(**parsed_kwargs)\n             ^^^^^^^^^^^^^^^^^^^^^^^^^^\nTypeError: PythonInterpreter.__init__() got an unexpected keyword argument \'code\''},
    reasoning='To solve the problem, I need to first add the increase of 300 to the initial value of 1200. This will give me a new value of 1500. Then, I will calculate 10% of this new value, which is 150. Finally, I will subtract this reduction from the new value (1500 - 150 = 1350) and round the result to the nearest whole number, which is 1350.',
    thought='The thought process involves straightforward arithmetic operations: first, I add the increase to the initial value, then calculate 10% of the resulting value, and finally subtract that percentage from the new value. The final step is rounding the result to ensure it is a whole number.',
    answer='1350'
)
ðŸŸ¢ PASSED

overall errors: python interpreter didn't work for a good amount of examples